Workbook

Sheet Shpjegim
A1: DITARI PERSONAL I MËSIMDHËNËSIT
A2: Ky tabelar është punuar për të lehtësuar punën e mësimdhënësve në vlerësimin e vazhdueshëm dhe atë përmbledhës duke u bazuar në udhëzimin administrativ të MASHTI mbi vlerësimin e nxënësve. Në të janë përfshirë 11 fleta tri prej të cilave janë "Shpjegimi"në fletën e parë me ngjyrë të kuqe, "Kalendari" me ngjyrë blu, "Orari i ziles" me ngjyrë portokalli dhe "mbuloja" (Koveri), fleta e fundit me ngjyrë të zezë. Në fletën "Koveri" janë të vendosura logot e shtetit, komunës dhe shkollës, emri dhe vendbanimi i shkollës që mund të ndryshohen varësisht nga shkolla, klasa, lënda dhe mësimdhënësi. Poshtë të njëjtës fletë është tabela me pasqyrën vjetore të suksesit të arritur, e shprehur edhe me mesatare dhe përqindje. Kjo tabelë plotësohet në mënyrë automatike, për këtë është vendosur edhe e fundit, ashtu që të plotësohet krejtësisht. 7 fletat tjera janë të njëjta, vetëm duhet ndërruar numrin e klasës, emrat dhe gjininë për meshkuj M dhe për femra F të nxënësve. Këto fleta kanë nga dy faqe ku në faqen e parë janë të dhënat për lëndën dhe mësimdhënësit, nga 4 instrumente të vlerësimit për të dy gjysmëvjetorët shkollor, si dhe përqindjet për vendosjen e kritereve në kuadër të secilit instrument të vlerësimit.Përqindjet dhe instrumentet mund të ndryshohen sipas preferencave të secilit. Shtylla për teste ka edhe numrin e pikëve që duhen për secilën notë bazuar në udhëzimin administrativ të MASHTI për vlerësim. Secili instrument ka nga 5 rubrika për vendosjen e notave nga 1 deri 5. Nota e secilit instrument llogaritet automatikisht. Në faqen e parë ndodhet edhe tabela me të dhënat rreth rezultateve të arritura të nxënësve gjatë vitit shkollor. I tërë tabelari është i printueshëm dhe arsyja pse nuk kam përdorur ngjyra është për të kursyer ngjyrën e printerëve që po na mungon. Më poshtë disa të dhëna për mënyrën e vlerësimit marrë nga udhëzimi administrativ i MASHTI.
A5:  Për një gjysmëvjetor vendosen dy nota, ku koha e planifikimit të vendosjes së tyre është e ndarë propocionalisht me kohëzgjatjen e gjysmëvjetorit  Llojet e instrumenteve për vlerësimin përmbledhës nuk duhen të jenë më pak se tri (3) instrumente vlerësimi.  Nota e vlerësimit për një gjysmëvjetor nxirret si mesatarja aritmetike e dy notave të vlerësimit përmbledhës  Ditari personal ruhet së paku për një shkallë kurrikulare.  Nota e vlerësimit përfundimtar për lëndën mësimore arrihet/vendoset me mesataren aritmetike të notave nga dy gjysmëvjetorët e vitit shkollor.

Sheet 6-1
A1: Punoi Naser A. Guri | B1: SHFMU "EMIN DURAKU" KAÇANIK | S1: Gjysmëvjetori | Y1: i parë, | AG1: i dytë, | AR1: Suksesi përfundimtar
D2: Viti shkollor: | I2: 2023/2024 | M2: Klasa: | P2: VI-1 | S2: Suksesi | X2: Nr. | Z2: % | AB2: M | AC2: F | AD2: gjithsej | AG2: Nr. | AI2: % | AK2: M | AM2: F | AO2: gjithsej | AR2: Nr. | AT2: % | AV2: M | AW2: F | AY2: gjithsej | BE2: NOTA 1 | BJ2: NOTA 2 | BK2: NOTA 1&2 | BL2: GJYSMËVJETORI I | BM2: GJYSMËVJETORI I | BN2: GJYSMËVJETORI II | BO2: GJYSMËVJETORI II | BP2: PËRFUNDIMTARI
S3: shkëlq | X3: =COUNTIF($BM$13:$BM$72,"5") -> 0 | Z3: =X3/$AD$3 -> #DIV/0! | AB3: =COUNTIFS($BM$13:$BM$72,"5",$D$13:$D$72,"M") -> 0 | AC3: =COUNTIFS($BM$13:$BM$72,"5",$D$13:$D$72,"F") -> 0 | AD3: =SUM(X3:Y7) -> 0 | AG3: =COUNTIF($BN$13:$BN$71,"5") -> 0 | AI3: =AG3/$AO$3 -> #DIV/0! | AK3: =COUNTIFS($BN$13:$BN$72,"5",$D$13:$D$72,"M") -> 0 | AM3: =COUNTIFS($BN$13:$BN$72,"5",$D$13:$D$72,"F") -> 0 | AO3: =SUM(AG3:AH7) -> 0 | AR3: =COUNTIF($AZ$13:$AZ$72,"5") -> 0 | AT3: =AR3/$AY$3 -> #DIV/0! | AV3: =COUNTIFS($AZ$13:$AZ$72,"5",$D$13:$D$72,"M") -> 0 | AW3: =COUNTIFS($AZ$13:$AZ$72,"5",$D$13:$D$72,"f") -> 0 | AY3: =SUM(AR3:AS7) -> 0
D4: Fusha kurrikulare | S4: sh.mirë | X4: =COUNTIF($BM$13:$BM$72,"4") -> 0 | Z4: =X4/$AD$3 -> #DIV/0! | AB4: =COUNTIFS($BM$13:$BM$72,"4",$D$13:$D$72,"M") -> 0 | AC4: =COUNTIFS($BM$13:$BM$72,"4",$D$13:$D$72,"F") -> 0 | AD4: Kalojnë | AG4: =COUNTIF($BN$13:$BN$71,"4") -> 0 | AI4: =AG4/$AO$3 -> #DIV/0! | AK4: =COUNTIFS($BN$13:$BN$72,"4",$D$13:$D$72,"M") -> 0 | AM4: =COUNTIFS($BN$13:$BN$72,"4",$D$13:$D$72,"F") -> 0 | AO4: Kalojnë | AR4: =COUNTIF($AZ$13:$AZ$72,"4") -> 0 | AT4: =AR4/$AY$3 -> #DIV/0! | AV4: =COUNTIFS($AZ$13:$AZ$72,"4",$D$13:$D$72,"M") -> 0 | AW4: =COUNTIFS($AZ$13:$AZ$72,"4",$D$13:$D$72,"F") -> 0 | AY4: Kalojnë
D5: Shkencat e natyrës | S5: mirë | X5: =COUNTIF($BM$13:$BM$72,"3") -> 0 | Z5: =X5/$AD$3 -> #DIV/0! | AB5: =COUNTIFS($BM$13:$BM$72,"3",$D$13:$D$72,"M") -> 0 | AC5: =COUNTIFS($BM$13:$BM$72,"3",$D$13:$D$72,"F") -> 0 | AD5: =SUM(X3:Y6) -> 0 | AG5: =COUNTIF($BN$13:$BN$71,"3") -> 0 | AI5: =AG5/$AO$3 -> #DIV/0! | AK5: =COUNTIFS($BN$13:$BN$72,"3",$D$13:$D$72,"M") -> 0 | AM5: =COUNTIFS($BN$13:$BN$72,"3",$D$13:$D$72,"F") -> 0 | AO5: =SUM(AG3:AH6) -> 0 | AR5: =COUNTIF($AZ$13:$AZ$72,"3") -> 0 | AT5: =AR5/$AY$3 -> #DIV/0! | AV5: =COUNTIFS($AZ$13:$AZ$72,"3",$D$13:$D$72,"M") -> 0 | AW5: =COUNTIFS($AZ$13:$AZ$72,"3",$D$13:$D$72,"F") -> 0 | AY5: =SUM(AQ3:AR6) -> 0
A6: Lënda: | D6: Biologji | S6: mjaft | X6: =COUNTIF($BM$13:$BM$72,"2") -> 0 | Z6: =X6/$AD$3 -> #DIV/0! | AB6: =COUNTIFS($BM$13:$BM$72,"2",$D$13:$D$72,"M") -> 0 | AC6: =COUNTIFS($BM$13:$BM$72,"2",$D$13:$D$72,"F") -> 0 | AD6: Mbesin | AG6: =COUNTIF($BN$13:$BN$71,"2") -> 0 | AI6: =AG6/$AO$3 -> #DIV/0! | AK6: =COUNTIFS($BN$13:$BN$72,"2",$D$13:$D$72,"M") -> 0 | AM6: =COUNTIFS($BN$13:$BN$72,"2",$D$13:$D$72,"F") -> 0 | AO6: Mbesin | AR6: =COUNTIF($AZ$13:$AZ$72,"2") -> 0 | AT6: =AR6/$AY$3 -> #DIV/0! | AV6: =COUNTIFS($AZ$13:$AZ$72,"2",$D$13:$D$72,"M") -> 0 | AW6: =COUNTIFS($AZ$13:$AZ$72,"2",$D$13:$D$72,"F") -> 0 | AY6: Mbesin
S7: pamjaft | X7: =COUNTIF($BM$13:$BM$72,"1") -> 0 | Z7: =X7/$AD$3 -> #DIV/0! | AB7: =COUNTIFS($BM$13:$BM$72,"1",$D$13:$D$72,"M") -> 0 | AC7: =COUNTIFS($BM$13:$BM$72,"1",$D$13:$D$72,"F") -> 0 | AD7: =X7 -> 0 | AG7: =COUNTIF($BN$13:$BN$71,"1") -> 0 | AI7: =AG7/$AO$3 -> #DIV/0! | AK7: =COUNTIFS($BN$13:$BN$72,"1",$D$13:$D$72,"M") -> 0 | AM7: =COUNTIFS($BN$13:$BN$72,"1",$D$13:$D$72,"F") -> 0 | AO7: =AG7 -> 0 | AR7: =COUNTIF($AZ$13:$AZ$72,"1") -> 0 | AT7: =AR7/$AY$3 -> #DIV/0! | AV7: =COUNTIFS($AZ$13:$AZ$72,"1",$D$13:$D$72,"M") -> 0 | AW7: =COUNTIFS($AZ$13:$AZ$72,"1",$D$13:$D$72,"F") -> 0 | AY7: =AR7 -> 0
A8: Mësimdhënësi-ja | D8: Naser Guri | S8: Nota mesatare GJ1 | AD8: =AVERAGEIF(BL13:BL72,">=1") -> #DIV/0! | AG8: GJ2 | AO8: =AVERAGEIF(BO13:BO72,">=1") -> #DIV/0! | AR8: Nota përfundimtare | AY8: =AVERAGEIF(BK13:BK72,">=1") -> #DIV/0!
A9: Instrumentet e vlerësimit | D9: Gjinia | E9: Gjysmëvjetori | F9: Angazhim në klasë | K9: Nota | L9: Detyra shtëpie | Q9: Nota | R9: Projekte & prezentime | W9: Nota | X9: Test | Z9: Nota | AA9: Nota 1 | AB9: Përfundim i vlerësimit 1 në anën e majtë dhe fillimi i vlerësimit përmbledhës 2 në anën e djathtë të tabelarit | AC9: Angazhim në klasë | AH9: Nota | AI9: Detyra shtëpie | AN9: Nota | AO9: Projekte & prezentime | AT9: Nota | AU9: Test | AW9: Nota | AX9: Nota 2 | AY9: Nota 1&2 | AZ9: Suksesi Përfundimtar
A11: Nr | B11: EMRAT DHE MBIEMRAT E NXËNËSVE
F12: 0.25 | L12: 0.15 | R12: 0.3 | X12: 0.3 | AA12: =F12+L12+R12+X12 -> 1 | AC12: 0.25 | AI12: 0.15 | AO12: 0.3 | AU12: 0.3 | AX12: =AC12+AI12+AO12+AU12 -> 1
A13: 1 | E13: 1 | K13: =AVERAGE(F13:J13) -> #DIV/0! | Q13: =AVERAGE(L13:P13) -> #DIV/0! | W13: =AVERAGE(R13:V13) -> #DIV/0! | Z13: =IF(X13>=85,"5",IF(X13>=65,"4",IF(X13>=55,"3",IF(X13>=40,"2",IF(X13>=1,"1",IF(X13>="","0")))))) -> 0 | AA13: =IF(BE13>=4.5, " 5 ", IF(BE13>=3.5," 4 ",IF(BE13>=2.5," 3 ",IF(BE13>=1.5," 2 ",IF(BE13>=1,"1 ",IF(BE13>=0,"0")))))) -> #DIV/0! | AH13: =AVERAGE(AC13:AG13) -> #DIV/0! | AN13: =AVERAGE(AI13:AM13) -> #DIV/0! | AT13: =AVERAGE(AO13:AS13) -> #DIV/0! | AW13: =IF(AU13>=85,"5",IF(AU13>=65,"4",IF(AU13>=55,"3",IF(AU13>=40,"2",IF(AU13>=1,"1",IF(AU13>="","0")))))) -> 0 | AX13: =IF(BJ13>=4.5, " 5 ", IF(BJ13>=3.5," 4 ",IF(BJ13>=2.5," 3 ",IF(BJ13>=1.5," 2 ",IF(BJ13>=1,"1 ",IF(BJ13>=0,"0")))))) -> #DIV/0! | AY13: =IF(BK13>=4.5, " 5 ", IF(BK13>=3.5," 4 ",IF(BK13>=2.5," 3 ",IF(BK13>=1.5," 2 ",IF(BK13>=1,"1 ",IF(BK13>=0,"0")))))) -> #DIV/0! | AZ13: =IF(BP13>=4.5, " 5 ", IF(BP13>=3.5," 4 ",IF(BP13>=2.5," 3 ",IF(BP13>=1.5," 2 ",IF(BP13>=1,"1 ",IF(BP13>=0,"0")))))) -> #DIV/0! | BA13: =$K13*$F$12 -> #DIV/0! | BB13: =Q13*L12 -> #DIV/0! | BC13: =$W13*$R$12 -> #DIV/0! | BD13: =$Z13*$X$12 -> 0 | BE13: =BA13+BB13+BC13+BD13 -> #DIV/0! | BF13: =$AH13*$AC$12 -> #DIV/0! | BG13: =$AN13*$AI$12 -> #DIV/0! | BH13: =$AT13*$AO$12 -> #DIV/0! | BI13: =$AW13*$AU$12 -> 0 | BJ13: =(BF13+BG13+BH13+BI13) -> #DIV/0! | BK13: =(BE13+BJ13)/2 -> #DIV/0! | BL13: =(BE13+BJ13)/2 -> #DIV/0! | BM13: =ROUND(BL13,) -> #DIV/0! | BN13: =ROUND(BO14,) -> #DIV/0! | BP13: =(AY13+AY14)/2 -> #DIV/0!
E14: 2 | K14: =AVERAGE(F14:J14) -> #DIV/0! | Q14: =AVERAGE(L14:P14) -> #DIV/0! | W14: =AVERAGE(R14:V14) -> #DIV/0! | Z14: =IF(X14>=85,"5",IF(X14>=65,"4",IF(X14>=55,"3",IF(X14>=40,"2",IF(X14>=1,"1",IF(X14>="","0")))))) -> 0 | AA14: =IF(BE14>=4.5, " 5 ", IF(BE14>=3.5," 4 ",IF(BE14>=2.5," 3 ",IF(BE14>=1.5," 2 ",IF(BE14>=1,"1 ",IF(BE14>=0,"0")))))) -> #DIV/0! | AH14: =AVERAGE(AC14:AG14) -> #DIV/0! | AN14: =AVERAGE(AI14:AM14) -> #DIV/0! | AT14: =AVERAGE(AO14:AS14) -> #DIV/0! | AW14: =IF(AU14>=85,"5",IF(AU14>=65,"4",IF(AU14>=55,"3",IF(AU14>=40,"2",IF(AU14>=1,"1",IF(AU14>="","0")))))) -> 0 | AX14: =IF(BJ14>=4.5, " 5 ", IF(BJ14>=3.5," 4 ",IF(BJ14>=2.5," 3 ",IF(BJ14>=1.5," 2 ",IF(BJ14>=1,"1 ",IF(BJ14>=0,"0")))))) -> #DIV/0! | AY14: =IF(BK14>=4.5, " 5 ", IF(BK14>=3.5," 4 ",IF(BK14>=2.5," 3 ",IF(BK14>=1.5," 2 ",IF(BK14>=1,"1 ",IF(BK14>=0,"0")))))) -> #DIV/0! | BA14: =$K14*$F$12 -> #DIV/0! | BB14: =$Q14*$L$12 -> #DIV/0! | BC14: =$W14*$R$12 -> #DIV/0! | BD14: =$Z14*$X$12 -> 0 | BE14: =BA14+BB14+BC14+BD14 -> #DIV/0! | BF14: =$AH14*$AC$12 -> #DIV/0! | BG14: =$AN14*$AI$12 -> #DIV/0! | BH14: =$AT14*$AO$12 -> #DIV/0! | BI14: =$AW14*$AU$12 -> 0 | BJ14: =(BF14+BG14+BH14+BI14) -> #DIV/0! | BK14: =(BE14+BJ14)/2 -> #DIV/0! | BO14: =(BE14+BJ14)/2 -> #DIV/0!
A15: 2 | E15: 1 | K15: =AVERAGE(F15:J15) -> #DIV/0! | Q15: =AVERAGE(L15:P15) -> #DIV/0! | W15: =AVERAGE(R15:V15) -> #DIV/0! | Z15: =IF(X15>=85,"5",IF(X15>=65,"4",IF(X15>=55,"3",IF(X15>=40,"2",IF(X15>=1,"1",IF(X15>="","0")))))) -> 0 | AA15: =IF(BE15>=4.5, " 5 ", IF(BE15>=3.5," 4 ",IF(BE15>=2.5," 3 ",IF(BE15>=1.5," 2 ",IF(BE15>=1,"1 ",IF(BE15>=0,"0")))))) -> #DIV/0! | AH15: =AVERAGE(AC15:AG15) -> #DIV/0! | AN15: =AVERAGE(AI15:AM15) -> #DIV/0! | AT15: =AVERAGE(AO15:AS15) -> #DIV/0! | AW15: =IF(AU15>=85,"5",IF(AU15>=65,"4",IF(AU15>=55,"3",IF(AU15>=40,"2",IF(AU15>=1,"1",IF(AU15>="","0")))))) -> 0 | AX15: =IF(BJ15>=4.5, " 5 ", IF(BJ15>=3.5," 4 ",IF(BJ15>=2.5," 3 ",IF(BJ15>=1.5," 2 ",IF(BJ15>=1,"1 ",IF(BJ15>=0,"0")))))) -> #DIV/0! | AY15: =IF(BK15>=4.5, " 5 ", IF(BK15>=3.5," 4 ",IF(BK15>=2.5," 3 ",IF(BK15>=1.5," 2 ",IF(BK15>=1,"1 ",IF(BK15>=0,"0")))))) -> #DIV/0! | AZ15: =IF(BP15>=4.5, " 5 ", IF(BP15>=3.5," 4 ",IF(BP15>=2.5," 3 ",IF(BP15>=1.5," 2 ",IF(BP15>=1,"1 ",IF(BP15>=0,"0")))))) -> #DIV/0! | BA15: =$K15*$F$12 -> #DIV/0! | BB15: =$Q15*$L$12 -> #DIV/0! | BC15: =$W15*$R$12 -> #DIV/0! | BD15: =$Z15*$X$12 -> 0 | BE15: =BA15+BB15+BC15+BD15 -> #DIV/0! | BF15: =$AH15*$AC$12 -> #DIV/0! | BG15: =$AN15*$AI$12 -> #DIV/0! | BH15: =$AT15*$AO$12 -> #DIV/0! | BI15: =$AW15*$AU$12 -> 0 | BJ15: =(BF15+BG15+BH15+BI15) -> #DIV/0! | BK15: =(BE15+BJ15)/2 -> #DIV/0! | BL15: =(BE15+BJ15)/2 -> #DIV/0! | BM15: =ROUND(BL15,) -> #DIV/0! | BN15: =ROUND(BO16,) -> #DIV/0! | BP15: =(AY15+AY16)/2 -> #DIV/0!
E16: 2 | K16: =AVERAGE(F16:J16) -> #DIV/0! | Q16: =AVERAGE(L16:P16) -> #DIV/0! | W16: =AVERAGE(R16:V16) -> #DIV/0! | Z16: =IF(X16>=85,"5",IF(X16>=65,"4",IF(X16>=55,"3",IF(X16>=40,"2",IF(X16>=1,"1",IF(X16>="","0")))))) -> 0 | AA16: =IF(BE16>=4.5, " 5 ", IF(BE16>=3.5," 4 ",IF(BE16>=2.5," 3 ",IF(BE16>=1.5," 2 ",IF(BE16>=1,"1 ",IF(BE16>=0,"0")))))) -> #DIV/0! | AH16: =AVERAGE(AC16:AG16) -> #DIV/0! | AN16: =AVERAGE(AI16:AM16) -> #DIV/0! | AT16: =AVERAGE(AO16:AS16) -> #DIV/0! | AW16: =IF(AU16>=85,"5",IF(AU16>=65,"4",IF(AU16>=55,"3",IF(AU16>=40,"2",IF(AU16>=1,"1",IF(AU16>="","0")))))) -> 0 | AX16: =IF(BJ16>=4.5, " 5 ", IF(BJ16>=3.5," 4 ",IF(BJ16>=2.5," 3 ",IF(BJ16>=1.5," 2 ",IF(BJ16>=1,"1 ",IF(BJ16>=0,"0")))))) -> #DIV/0! | AY16: =IF(BK16>=4.5, " 5 ", IF(BK16>=3.5," 4 ",IF(BK16>=2.5," 3 ",IF(BK16>=1.5," 2 ",IF(BK16>=1,"1 ",IF(BK16>=0,"0")))))) -> #DIV/0! | BA16: =$K16*$F$12 -> #DIV/0! | BB16: =$Q16*$L$12 -> #DIV/0! | BC16: =$W16*$R$12 -> #DIV/0! | BD16: =$Z16*$X$12 -> 0 | BE16: =BA16+BB16+BC16+BD16 -> #DIV/0! | BF16: =$AH16*$AC$12 -> #DIV/0! | BG16: =$AN16*$AI$12 -> #DIV/0! | BH16: =$AT16*$AO$12 -> #DIV/0! | BI16: =$AW16*$AU$12 -> 0 | BJ16: =(BF16+BG16+BH16+BI16) -> #DIV/0! | BK16: =(BE16+BJ16)/2 -> #DIV/0! | BO16: =(BE16+BJ16)/2 -> #DIV/0!
A17: 3 | E17: 1 | K17: =AVERAGE(F17:J17) -> #DIV/0! | Q17: =AVERAGE(L17:P17) -> #DIV/0! | W17: =AVERAGE(R17:V17) -> #DIV/0! | Z17: =IF(X17>=85,"5",IF(X17>=65,"4",IF(X17>=55,"3",IF(X17>=40,"2",IF(X17>=1,"1",IF(X17>="","0")))))) -> 0 | AA17: =IF(BE17>=4.5, " 5 ", IF(BE17>=3.5," 4 ",IF(BE17>=2.5," 3 ",IF(BE17>=1.5," 2 ",IF(BE17>=1,"1 ",IF(BE17>=0,"0")))))) -> #DIV/0! | AH17: =AVERAGE(AC17:AG17) -> #DIV/0! | AN17: =AVERAGE(AI17:AM17) -> #DIV/0! | AT17: =AVERAGE(AO17:AS17) -> #DIV/0! | AW17: =IF(AU17>=85,"5",IF(AU17>=65,"4",IF(AU17>=55,"3",IF(AU17>=40,"2",IF(AU17>=1,"1",IF(AU17>="","0")))))) -> 0 | AX17: =IF(BJ17>=4.5, " 5 ", IF(BJ17>=3.5," 4 ",IF(BJ17>=2.5," 3 ",IF(BJ17>=1.5," 2 ",IF(BJ17>=1,"1 ",IF(BJ17>=0,"0")))))) -> #DIV/0! | AY17: =IF(BK17>=4.5, " 5 ", IF(BK17>=3.5," 4 ",IF(BK17>=2.5," 3 ",IF(BK17>=1.5," 2 ",IF(BK17>=1,"1 ",IF(BK17>=0,"0")))))) -> #DIV/0! | AZ17: =IF(BP17>=4.5, " 5 ", IF(BP17>=3.5," 4 ",IF(BP17>=2.5," 3 ",IF(BP17>=1.5," 2 ",IF(BP17>=1,"1 ",IF(BP17>=0,"0")))))) -> #DIV/0! | BA17: =$K17*$F$12 -> #DIV/0! | BB17: =$Q17*$L$12 -> #DIV/0! | BC17: =$W17*$R$12 -> #DIV/0! | BD17: =$Z17*$X$12 -> 0 | BE17: =BA17+BB17+BC17+BD17 -> #DIV/0! | BF17: =$AH17*$AC$12 -> #DIV/0! | BG17: =$AN17*$AI$12 -> #DIV/0! | BH17: =$AT17*$AO$12 -> #DIV/0! | BI17: =$AW17*$AU$12 -> 0 | BJ17: =(BF17+BG17+BH17+BI17) -> #DIV/0! | BK17: =(BE17+BJ17)/2 -> #DIV/0! | BL17: =(BE17+BJ17)/2 -> #DIV/0! | BM17: =ROUND(BL17,) -> #DIV/0! | BN17: =ROUND(BO18,) -> #DIV/0! | BP17: =(AY17+AY18)/2 -> #DIV/0!
E18: 2 | K18: =AVERAGE(F18:J18) -> #DIV/0! | Q18: =AVERAGE(L18:P18) -> #DIV/0! | W18: =AVERAGE(R18:V18) -> #DIV/0! | Z18: =IF(X18>=85,"5",IF(X18>=65,"4",IF(X18>=55,"3",IF(X18>=40,"2",IF(X18>=1,"1",IF(X18>="","0")))))) -> 0 | AA18: =IF(BE18>=4.5, " 5 ", IF(BE18>=3.5," 4 ",IF(BE18>=2.5," 3 ",IF(BE18>=1.5," 2 ",IF(BE18>=1,"1 ",IF(BE18>=0,"0")))))) -> #DIV/0! | AH18: =AVERAGE(AC18:AG18) -> #DIV/0! | AN18: =AVERAGE(AI18:AM18) -> #DIV/0! | AT18: =AVERAGE(AO18:AS18) -> #DIV/0! | AW18: =IF(AU18>=85,"5",IF(AU18>=65,"4",IF(AU18>=55,"3",IF(AU18>=40,"2",IF(AU18>=1,"1",IF(AU18>="","0")))))) -> 0 | AX18: =IF(BJ18>=4.5, " 5 ", IF(BJ18>=3.5," 4 ",IF(BJ18>=2.5," 3 ",IF(BJ18>=1.5," 2 ",IF(BJ18>=1,"1 ",IF(BJ18>=0,"0")))))) -> #DIV/0! | AY18: =IF(BK18>=4.5, " 5 ", IF(BK18>=3.5," 4 ",IF(BK18>=2.5," 3 ",IF(BK18>=1.5," 2 ",IF(BK18>=1,"1 ",IF(BK18>=0,"0")))))) -> #DIV/0! | BA18: =$K18*$F$12 -> #DIV/0! | BB18: =$Q18*$L$12 -> #DIV/0! | BC18: =$W18*$R$12 -> #DIV/0! | BD18: =$Z18*$X$12 -> 0 | BE18: =BA18+BB18+BC18+BD18 -> #DIV/0! | BF18: =$AH18*$AC$12 -> #DIV/0! | BG18: =$AN18*$AI$12 -> #DIV/0! | BH18: =$AT18*$AO$12 -> #DIV/0! | BI18: =$AW18*$AU$12 -> 0 | BJ18: =(BF18+BG18+BH18+BI18) -> #DIV/0! | BK18: =(BE18+BJ18)/2 -> #DIV/0! | BO18: =(BE18+BJ18)/2 -> #DIV/0!
A19: 4 | E19: 1 | K19: =AVERAGE(F19:J19) -> #DIV/0! | Q19: =AVERAGE(L19:P19) -> #DIV/0! | W19: =AVERAGE(R19:V19) -> #DIV/0! | Z19: =IF(X19>=85,"5",IF(X19>=65,"4",IF(X19>=55,"3",IF(X19>=40,"2",IF(X19>=1,"1",IF(X19>="","0")))))) -> 0 | AA19: =IF(BE19>=4.5, " 5 ", IF(BE19>=3.5," 4 ",IF(BE19>=2.5," 3 ",IF(BE19>=1.5," 2 ",IF(BE19>=1,"1 ",IF(BE19>=0,"0")))))) -> #DIV/0! | AH19: =AVERAGE(AC19:AG19) -> #DIV/0! | AN19: =AVERAGE(AI19:AM19) -> #DIV/0! | AT19: =AVERAGE(AO19:AS19) -> #DIV/0! | AW19: =IF(AU19>=85,"5",IF(AU19>=65,"4",IF(AU19>=55,"3",IF(AU19>=40,"2",IF(AU19>=1,"1",IF(AU19>="","0")))))) -> 0 | AX19: =IF(BJ19>=4.5, " 5 ", IF(BJ19>=3.5," 4 ",IF(BJ19>=2.5," 3 ",IF(BJ19>=1.5," 2 ",IF(BJ19>=1,"1 ",IF(BJ19>=0,"0")))))) -> #DIV/0! | AY19: =IF(BK19>=4.5, " 5 ", IF(BK19>=3.5," 4 ",IF(BK19>=2.5," 3 ",IF(BK19>=1.5," 2 ",IF(BK19>=1,"1 ",IF(BK19>=0,"0")))))) -> #DIV/0! | AZ19: =IF(BP19>=4.5, " 5 ", IF(BP19>=3.5," 4 ",IF(BP19>=2.5," 3 ",IF(BP19>=1.5," 2 ",IF(BP19>=1,"1 ",IF(BP19>=0,"0")))))) -> #DIV/0! | BA19: =$K19*$F$12 -> #DIV/0! | BB19: =$Q19*$L$12 -> #DIV/0! | BC19: =$W19*$R$12 -> #DIV/0! | BD19: =$Z19*$X$12 -> 0 | BE19: =BA19+BB19+BC19+BD19 -> #DIV/0! | BF19: =$AH19*$AC$12 -> #DIV/0! | BG19: =$AN19*$AI$12 -> #DIV/0! | BH19: =$AT19*$AO$12 -> #DIV/0! | BI19: =$AW19*$AU$12 -> 0 | BJ19: =(BF19+BG19+BH19+BI19) -> #DIV/0! | BK19: =(BE19+BJ19)/2 -> #DIV/0! | BL19: =(BE19+BJ19)/2 -> #DIV/0! | BM19: =ROUND(BL19,) -> #DIV/0! | BN19: =ROUND(BO20,) -> #DIV/0! | BP19: =(AY19+AY20)/2 -> #DIV/0!
E20: 2 | K20: =AVERAGE(F20:J20) -> #DIV/0! | Q20: =AVERAGE(L20:P20) -> #DIV/0! | W20: =AVERAGE(R20:V20) -> #DIV/0! | Z20: =IF(X20>=85,"5",IF(X20>=65,"4",IF(X20>=55,"3",IF(X20>=40,"2",IF(X20>=1,"1",IF(X20>="","0")))))) -> 0 | AA20: =IF(BE20>=4.5, " 5 ", IF(BE20>=3.5," 4 ",IF(BE20>=2.5," 3 ",IF(BE20>=1.5," 2 ",IF(BE20>=1,"1 ",IF(BE20>=0,"0")))))) -> #DIV/0! | AH20: =AVERAGE(AC20:AG20) -> #DIV/0! | AN20: =AVERAGE(AI20:AM20) -> #DIV/0! | AT20: =AVERAGE(AO20:AS20) -> #DIV/0! | AW20: =IF(AU20>=85,"5",IF(AU20>=65,"4",IF(AU20>=55,"3",IF(AU20>=40,"2",IF(AU20>=1,"1",IF(AU20>="","0")))))) -> 0 | AX20: =IF(BJ20>=4.5, " 5 ", IF(BJ20>=3.5," 4 ",IF(BJ20>=2.5," 3 ",IF(BJ20>=1.5," 2 ",IF(BJ20>=1,"1 ",IF(BJ20>=0,"0")))))) -> #DIV/0! | AY20: =IF(BK20>=4.5, " 5 ", IF(BK20>=3.5," 4 ",IF(BK20>=2.5," 3 ",IF(BK20>=1.5," 2 ",IF(BK20>=1,"1 ",IF(BK20>=0,"0")))))) -> #DIV/0! | BA20: =$K20*$F$12 -> #DIV/0! | BB20: =$Q20*$L$12 -> #DIV/0! | BC20: =$W20*$R$12 -> #DIV/0! | BD20: =$Z20*$X$12 -> 0 | BE20: =BA20+BB20+BC20+BD20 -> #DIV/0! | BF20: =$AH20*$AC$12 -> #DIV/0! | BG20: =$AN20*$AI$12 -> #DIV/0! | BH20: =$AT20*$AO$12 -> #DIV/0! | BI20: =$AW20*$AU$12 -> 0 | BJ20: =(BF20+BG20+BH20+BI20) -> #DIV/0! | BK20: =(BE20+BJ20)/2 -> #DIV/0! | BO20: =(BE20+BJ20)/2 -> #DIV/0!
A21: 5 | E21: 1 | K21: =AVERAGE(F21:J21) -> #DIV/0! | Q21: =AVERAGE(L21:P21) -> #DIV/0! | W21: =AVERAGE(R21:V21) -> #DIV/0! | Z21: =IF(X21>=85,"5",IF(X21>=65,"4",IF(X21>=55,"3",IF(X21>=40,"2",IF(X21>=1,"1",IF(X21>="","0")))))) -> 0 | AA21: =IF(BE21>=4.5, " 5 ", IF(BE21>=3.5," 4 ",IF(BE21>=2.5," 3 ",IF(BE21>=1.5," 2 ",IF(BE21>=1,"1 ",IF(BE21>=0,"0")))))) -> #DIV/0! | AH21: =AVERAGE(AC21:AG21) -> #DIV/0! | AN21: =AVERAGE(AI21:AM21) -> #DIV/0! | AT21: =AVERAGE(AO21:AS21) -> #DIV/0! | AW21: =IF(AU21>=85,"5",IF(AU21>=65,"4",IF(AU21>=55,"3",IF(AU21>=40,"2",IF(AU21>=1,"1",IF(AU21>="","0")))))) -> 0 | AX21: =IF(BJ21>=4.5, " 5 ", IF(BJ21>=3.5," 4 ",IF(BJ21>=2.5," 3 ",IF(BJ21>=1.5," 2 ",IF(BJ21>=1,"1 ",IF(BJ21>=0,"0")))))) -> #DIV/0! | AY21: =IF(BK21>=4.5, " 5 ", IF(BK21>=3.5," 4 ",IF(BK21>=2.5," 3 ",IF(BK21>=1.5," 2 ",IF(BK21>=1,"1 ",IF(BK21>=0,"0")))))) -> #DIV/0! | AZ21: =IF(BP21>=4.5, " 5 ", IF(BP21>=3.5," 4 ",IF(BP21>=2.5," 3 ",IF(BP21>=1.5," 2 ",IF(BP21>=1,"1 ",IF(BP21>=0,"0")))))) -> #DIV/0! | BA21: =$K21*$F$12 -> #DIV/0! | BB21: =$Q21*$L$12 -> #DIV/0! | BC21: =$W21*$R$12 -> #DIV/0! | BD21: =$Z21*$X$12 -> 0 | BE21: =BA21+BB21+BC21+BD21 -> #DIV/0! | BF21: =$AH21*$AC$12 -> #DIV/0! | BG21: =$AN21*$AI$12 -> #DIV/0! | BH21: =$AT21*$AO$12 -> #DIV/0! | BI21: =$AW21*$AU$12 -> 0 | BJ21: =(BF21+BG21+BH21+BI21) -> #DIV/0! | BK21: =(BE21+BJ21)/2 -> #DIV/0! | BL21: =(BE21+BJ21)/2 -> #DIV/0! | BM21: =ROUND(BL21,) -> #DIV/0! | BN21: =ROUND(BO22,) -> #DIV/0! | BP21: =(AY21+AY22)/2 -> #DIV/0!
E22: 2 | K22: =AVERAGE(F22:J22) -> #DIV/0! | Q22: =AVERAGE(L22:P22) -> #DIV/0! | W22: =AVERAGE(R22:V22) -> #DIV/0! | Z22: =IF(X22>=85,"5",IF(X22>=65,"4",IF(X22>=55,"3",IF(X22>=40,"2",IF(X22>=1,"1",IF(X22>="","0")))))) -> 0 | AA22: =IF(BE22>=4.5, " 5 ", IF(BE22>=3.5," 4 ",IF(BE22>=2.5," 3 ",IF(BE22>=1.5," 2 ",IF(BE22>=1,"1 ",IF(BE22>=0,"0")))))) -> #DIV/0! | AH22: =AVERAGE(AC22:AG22) -> #DIV/0! | AN22: =AVERAGE(AI22:AM22) -> #DIV/0! | AT22: =AVERAGE(AO22:AS22) -> #DIV/0! | AW22: =IF(AU22>=85,"5",IF(AU22>=65,"4",IF(AU22>=55,"3",IF(AU22>=40,"2",IF(AU22>=1,"1",IF(AU22>="","0")))))) -> 0 | AX22: =IF(BJ22>=4.5, " 5 ", IF(BJ22>=3.5," 4 ",IF(BJ22>=2.5," 3 ",IF(BJ22>=1.5," 2 ",IF(BJ22>=1,"1 ",IF(BJ22>=0,"0")))))) -> #DIV/0! | AY22: =IF(BK22>=4.5, " 5 ", IF(BK22>=3.5," 4 ",IF(BK22>=2.5," 3 ",IF(BK22>=1.5," 2 ",IF(BK22>=1,"1 ",IF(BK22>=0,"0")))))) -> #DIV/0! | BA22: =$K22*$F$12 -> #DIV/0! | BB22: =$Q22*$L$12 -> #DIV/0! | BC22: =$W22*$R$12 -> #DIV/0! | BD22: =$Z22*$X$12 -> 0 | BE22: =BA22+BB22+BC22+BD22 -> #DIV/0! | BF22: =$AH22*$AC$12 -> #DIV/0! | BG22: =$AN22*$AI$12 -> #DIV/0! | BH22: =$AT22*$AO$12 -> #DIV/0! | BI22: =$AW22*$AU$12 -> 0 | BJ22: =(BF22+BG22+BH22+BI22) -> #DIV/0! | BK22: =(BE22+BJ22)/2 -> #DIV/0! | BO22: =(BE22+BJ22)/2 -> #DIV/0!
A23: 6 | E23: 1 | K23: =AVERAGE(F23:J23) -> #DIV/0! | Q23: =AVERAGE(L23:P23) -> #DIV/0! | W23: =AVERAGE(R23:V23) -> #DIV/0! | Z23: =IF(X23>=85,"5",IF(X23>=65,"4",IF(X23>=55,"3",IF(X23>=40,"2",IF(X23>=1,"1",IF(X23>="","0")))))) -> 0 | AA23: =IF(BE23>=4.5, " 5 ", IF(BE23>=3.5," 4 ",IF(BE23>=2.5," 3 ",IF(BE23>=1.5," 2 ",IF(BE23>=1,"1 ",IF(BE23>=0,"0")))))) -> #DIV/0! | AH23: =AVERAGE(AC23:AG23) -> #DIV/0! | AN23: =AVERAGE(AI23:AM23) -> #DIV/0! | AT23: =AVERAGE(AO23:AS23) -> #DIV/0! | AW23: =IF(AU23>=85,"5",IF(AU23>=65,"4",IF(AU23>=55,"3",IF(AU23>=40,"2",IF(AU23>=1,"1",IF(AU23>="","0")))))) -> 0 | AX23: =IF(BJ23>=4.5, " 5 ", IF(BJ23>=3.5," 4 ",IF(BJ23>=2.5," 3 ",IF(BJ23>=1.5," 2 ",IF(BJ23>=1,"1 ",IF(BJ23>=0,"0")))))) -> #DIV/0! | AY23: =IF(BK23>=4.5, " 5 ", IF(BK23>=3.5," 4 ",IF(BK23>=2.5," 3 ",IF(BK23>=1.5," 2 ",IF(BK23>=1,"1 ",IF(BK23>=0,"0")))))) -> #DIV/0! | AZ23: =IF(BP23>=4.5, " 5 ", IF(BP23>=3.5," 4 ",IF(BP23>=2.5," 3 ",IF(BP23>=1.5," 2 ",IF(BP23>=1,"1 ",IF(BP23>=0,"0")))))) -> #DIV/0! | BA23: =$K23*$F$12 -> #DIV/0! | BB23: =$Q23*$L$12 -> #DIV/0! | BC23: =$W23*$R$12 -> #DIV/0! | BD23: =$Z23*$X$12 -> 0 | BE23: =BA23+BB23+BC23+BD23 -> #DIV/0! | BF23: =$AH23*$AC$12 -> #DIV/0! | BG23: =$AN23*$AI$12 -> #DIV/0! | BH23: =$AT23*$AO$12 -> #DIV/0! | BI23: =$AW23*$AU$12 -> 0 | BJ23: =(BF23+BG23+BH23+BI23) -> #DIV/0! | BK23: =(BE23+BJ23)/2 -> #DIV/0! | BL23: =(BE23+BJ23)/2 -> #DIV/0! | BM23: =ROUND(BL23,) -> #DIV/0! | BN23: =ROUND(BO24,) -> #DIV/0! | BP23: =(AY23+AY24)/2 -> #DIV/0!
E24: 2 | K24: =AVERAGE(F24:J24) -> #DIV/0! | Q24: =AVERAGE(L24:P24) -> #DIV/0! | W24: =AVERAGE(R24:V24) -> #DIV/0! | Z24: =IF(X24>=85,"5",IF(X24>=65,"4",IF(X24>=55,"3",IF(X24>=40,"2",IF(X24>=1,"1",IF(X24>="","0")))))) -> 0 | AA24: =IF(BE24>=4.5, " 5 ", IF(BE24>=3.5," 4 ",IF(BE24>=2.5," 3 ",IF(BE24>=1.5," 2 ",IF(BE24>=1,"1 ",IF(BE24>=0,"0")))))) -> #DIV/0! | AH24: =AVERAGE(AC24:AG24) -> #DIV/0! | AN24: =AVERAGE(AI24:AM24) -> #DIV/0! | AT24: =AVERAGE(AO24:AS24) -> #DIV/0! | AW24: =IF(AU24>=85,"5",IF(AU24>=65,"4",IF(AU24>=55,"3",IF(AU24>=40,"2",IF(AU24>=1,"1",IF(AU24>="","0")))))) -> 0 | AX24: =IF(BJ24>=4.5, " 5 ", IF(BJ24>=3.5," 4 ",IF(BJ24>=2.5," 3 ",IF(BJ24>=1.5," 2 ",IF(BJ24>=1,"1 ",IF(BJ24>=0,"0")))))) -> #DIV/0! | AY24: =IF(BK24>=4.5, " 5 ", IF(BK24>=3.5," 4 ",IF(BK24>=2.5," 3 ",IF(BK24>=1.5," 2 ",IF(BK24>=1,"1 ",IF(BK24>=0,"0")))))) -> #DIV/0! | BA24: =$K24*$F$12 -> #DIV/0! | BB24: =$Q24*$L$12 -> #DIV/0! | BC24: =$W24*$R$12 -> #DIV/0! | BD24: =$Z24*$X$12 -> 0 | BE24: =BA24+BB24+BC24+BD24 -> #DIV/0! | BF24: =$AH24*$AC$12 -> #DIV/0! | BG24: =$AN24*$AI$12 -> #DIV/0! | BH24: =$AT24*$AO$12 -> #DIV/0! | BI24: =$AW24*$AU$12 -> 0 | BJ24: =(BF24+BG24+BH24+BI24) -> #DIV/0! | BK24: =(BE24+BJ24)/2 -> #DIV/0! | BO24: =(BE24+BJ24)/2 -> #DIV/0!
A25: 7 | E25: 1 | K25: =AVERAGE(F25:J25) -> #DIV/0! | Q25: =AVERAGE(L25:P25) -> #DIV/0! | W25: =AVERAGE(R25:V25) -> #DIV/0! | Z25: =IF(X25>=85,"5",IF(X25>=65,"4",IF(X25>=55,"3",IF(X25>=40,"2",IF(X25>=1,"1",IF(X25>="","0")))))) -> 0 | AA25: =IF(BE25>=4.5, " 5 ", IF(BE25>=3.5," 4 ",IF(BE25>=2.5," 3 ",IF(BE25>=1.5," 2 ",IF(BE25>=1,"1 ",IF(BE25>=0,"0")))))) -> #DIV/0! | AH25: =AVERAGE(AC25:AG25) -> #DIV/0! | AN25: =AVERAGE(AI25:AM25) -> #DIV/0! | AT25: =AVERAGE(AO25:AS25) -> #DIV/0! | AW25: =IF(AU25>=85,"5",IF(AU25>=65,"4",IF(AU25>=55,"3",IF(AU25>=40,"2",IF(AU25>=1,"1",IF(AU25>="","0")))))) -> 0 | AX25: =IF(BJ25>=4.5, " 5 ", IF(BJ25>=3.5," 4 ",IF(BJ25>=2.5," 3 ",IF(BJ25>=1.5," 2 ",IF(BJ25>=1,"1 ",IF(BJ25>=0,"0")))))) -> #DIV/0! | AY25: =IF(BK25>=4.5, " 5 ", IF(BK25>=3.5," 4 ",IF(BK25>=2.5," 3 ",IF(BK25>=1.5," 2 ",IF(BK25>=1,"1 ",IF(BK25>=0,"0")))))) -> #DIV/0! | AZ25: =IF(BP25>=4.5, " 5 ", IF(BP25>=3.5," 4 ",IF(BP25>=2.5," 3 ",IF(BP25>=1.5," 2 ",IF(BP25>=1,"1 ",IF(BP25>=0,"0")))))) -> #DIV/0! | BA25: =$K25*$F$12 -> #DIV/0! | BB25: =$Q25*$L$12 -> #DIV/0! | BC25: =$W25*$R$12 -> #DIV/0! | BD25: =$Z25*$X$12 -> 0 | BE25: =BA25+BB25+BC25+BD25 -> #DIV/0! | BF25: =$AH25*$AC$12 -> #DIV/0! | BG25: =$AN25*$AI$12 -> #DIV/0! | BH25: =$AT25*$AO$12 -> #DIV/0! | BI25: =$AW25*$AU$12 -> 0 | BJ25: =(BF25+BG25+BH25+BI25) -> #DIV/0! | BK25: =(BE25+BJ25)/2 -> #DIV/0! | BL25: =(BE25+BJ25)/2 -> #DIV/0! | BM25: =ROUND(BL25,) -> #DIV/0! | BN25: =ROUND(BO26,) -> #DIV/0! | BP25: =(AY25+AY26)/2 -> #DIV/0!
E26: 2 | K26: =AVERAGE(F26:J26) -> #DIV/0! | Q26: =AVERAGE(L26:P26) -> #DIV/0! | W26: =AVERAGE(R26:V26) -> #DIV/0! | Z26: =IF(X26>=85,"5",IF(X26>=65,"4",IF(X26>=55,"3",IF(X26>=40,"2",IF(X26>=1,"1",IF(X26>="","0")))))) -> 0 | AA26: =IF(BE26>=4.5, " 5 ", IF(BE26>=3.5," 4 ",IF(BE26>=2.5," 3 ",IF(BE26>=1.5," 2 ",IF(BE26>=1,"1 ",IF(BE26>=0,"0")))))) -> #DIV/0! | AH26: =AVERAGE(AC26:AG26) -> #DIV/0! | AN26: =AVERAGE(AI26:AM26) -> #DIV/0! | AT26: =AVERAGE(AO26:AS26) -> #DIV/0! | AW26: =IF(AU26>=85,"5",IF(AU26>=65,"4",IF(AU26>=55,"3",IF(AU26>=40,"2",IF(AU26>=1,"1",IF(AU26>="","0")))))) -> 0 | AX26: =IF(BJ26>=4.5, " 5 ", IF(BJ26>=3.5," 4 ",IF(BJ26>=2.5," 3 ",IF(BJ26>=1.5," 2 ",IF(BJ26>=1,"1 ",IF(BJ26>=0,"0")))))) -> #DIV/0! | AY26: =IF(BK26>=4.5, " 5 ", IF(BK26>=3.5," 4 ",IF(BK26>=2.5," 3 ",IF(BK26>=1.5," 2 ",IF(BK26>=1,"1 ",IF(BK26>=0,"0")))))) -> #DIV/0! | BA26: =$K26*$F$12 -> #DIV/0! | BB26: =$Q26*$L$12 -> #DIV/0! | BC26: =$W26*$R$12 -> #DIV/0! | BD26: =$Z26*$X$12 -> 0 | BE26: =BA26+BB26+BC26+BD26 -> #DIV/0! | BF26: =$AH26*$AC$12 -> #DIV/0! | BG26: =$AN26*$AI$12 -> #DIV/0! | BH26: =$AT26*$AO$12 -> #DIV/0! | BI26: =$AW26*$AU$12 -> 0 | BJ26: =(BF26+BG26+BH26+BI26) -> #DIV/0! | BK26: =(BE26+BJ26)/2 -> #DIV/0! | BO26: =(BE26+BJ26)/2 -> #DIV/0!
A27: 8 | E27: 1 | K27: =AVERAGE(F27:J27) -> #DIV/0! | Q27: =AVERAGE(L27:P27) -> #DIV/0! | W27: =AVERAGE(R27:V27) -> #DIV/0! | Z27: =IF(X27>=85,"5",IF(X27>=65,"4",IF(X27>=55,"3",IF(X27>=40,"2",IF(X27>=1,"1",IF(X27>="","0")))))) -> 0 | AA27: =IF(BE27>=4.5, " 5 ", IF(BE27>=3.5," 4 ",IF(BE27>=2.5," 3 ",IF(BE27>=1.5," 2 ",IF(BE27>=1,"1 ",IF(BE27>=0,"0")))))) -> #DIV/0! | AH27: =AVERAGE(AC27:AG27) -> #DIV/0! | AN27: =AVERAGE(AI27:AM27) -> #DIV/0! | AT27: =AVERAGE(AO27:AS27) -> #DIV/0! | AW27: =IF(AU27>=85,"5",IF(AU27>=65,"4",IF(AU27>=55,"3",IF(AU27>=40,"2",IF(AU27>=1,"1",IF(AU27>="","0")))))) -> 0 | AX27: =IF(BJ27>=4.5, " 5 ", IF(BJ27>=3.5," 4 ",IF(BJ27>=2.5," 3 ",IF(BJ27>=1.5," 2 ",IF(BJ27>=1,"1 ",IF(BJ27>=0,"0")))))) -> #DIV/0! | AY27: =IF(BK27>=4.5, " 5 ", IF(BK27>=3.5," 4 ",IF(BK27>=2.5," 3 ",IF(BK27>=1.5," 2 ",IF(BK27>=1,"1 ",IF(BK27>=0,"0")))))) -> #DIV/0! | AZ27: =IF(BP27>=4.5, " 5 ", IF(BP27>=3.5," 4 ",IF(BP27>=2.5," 3 ",IF(BP27>=1.5," 2 ",IF(BP27>=1,"1 ",IF(BP27>=0,"0")))))) -> #DIV/0! | BA27: =$K27*$F$12 -> #DIV/0! | BB27: =$Q27*$L$12 -> #DIV/0! | BC27: =$W27*$R$12 -> #DIV/0! | BD27: =$Z27*$X$12 -> 0 | BE27: =BA27+BB27+BC27+BD27 -> #DIV/0! | BF27: =$AH27*$AC$12 -> #DIV/0! | BG27: =$AN27*$AI$12 -> #DIV/0! | BH27: =$AT27*$AO$12 -> #DIV/0! | BI27: =$AW27*$AU$12 -> 0 | BJ27: =(BF27+BG27+BH27+BI27) -> #DIV/0! | BK27: =(BE27+BJ27)/2 -> #DIV/0! | BL27: =(BE27+BJ27)/2 -> #DIV/0! | BM27: =ROUND(BL27,) -> #DIV/0! | BN27: =ROUND(BO28,) -> #DIV/0! | BP27: =(AY27+AY28)/2 -> #DIV/0!
E28: 2 | K28: =AVERAGE(F28:J28) -> #DIV/0! | Q28: =AVERAGE(L28:P28) -> #DIV/0! | W28: =AVERAGE(R28:V28) -> #DIV/0! | Z28: =IF(X28>=85,"5",IF(X28>=65,"4",IF(X28>=55,"3",IF(X28>=40,"2",IF(X28>=1,"1",IF(X28>="","0")))))) -> 0 | AA28: =IF(BE28>=4.5, " 5 ", IF(BE28>=3.5," 4 ",IF(BE28>=2.5," 3 ",IF(BE28>=1.5," 2 ",IF(BE28>=1,"1 ",IF(BE28>=0,"0")))))) -> #DIV/0! | AH28: =AVERAGE(AC28:AG28) -> #DIV/0! | AN28: =AVERAGE(AI28:AM28) -> #DIV/0! | AT28: =AVERAGE(AO28:AS28) -> #DIV/0! | AW28: =IF(AU28>=85,"5",IF(AU28>=65,"4",IF(AU28>=55,"3",IF(AU28>=40,"2",IF(AU28>=1,"1",IF(AU28>="","0")))))) -> 0 | AX28: =IF(BJ28>=4.5, " 5 ", IF(BJ28>=3.5," 4 ",IF(BJ28>=2.5," 3 ",IF(BJ28>=1.5," 2 ",IF(BJ28>=1,"1 ",IF(BJ28>=0,"0")))))) -> #DIV/0! | AY28: =IF(BK28>=4.5, " 5 ", IF(BK28>=3.5," 4 ",IF(BK28>=2.5," 3 ",IF(BK28>=1.5," 2 ",IF(BK28>=1,"1 ",IF(BK28>=0,"0")))))) -> #DIV/0! | BA28: =$K28*$F$12 -> #DIV/0! | BB28: =$Q28*$L$12 -> #DIV/0! | BC28: =$W28*$R$12 -> #DIV/0! | BD28: =$Z28*$X$12 -> 0 | BE28: =BA28+BB28+BC28+BD28 -> #DIV/0! | BF28: =$AH28*$AC$12 -> #DIV/0! | BG28: =$AN28*$AI$12 -> #DIV/0! | BH28: =$AT28*$AO$12 -> #DIV/0! | BI28: =$AW28*$AU$12 -> 0 | BJ28: =(BF28+BG28+BH28+BI28) -> #DIV/0! | BK28: =(BE28+BJ28)/2 -> #DIV/0! | BO28: =(BE28+BJ28)/2 -> #DIV/0!
A29: 9 | E29: 1 | K29: =AVERAGE(F29:J29) -> #DIV/0! | Q29: =AVERAGE(L29:P29) -> #DIV/0! | W29: =AVERAGE(R29:V29) -> #DIV/0! | Z29: =IF(X29>=85,"5",IF(X29>=65,"4",IF(X29>=55,"3",IF(X29>=40,"2",IF(X29>=1,"1",IF(X29>="","0")))))) -> 0 | AA29: =IF(BE29>=4.5, " 5 ", IF(BE29>=3.5," 4 ",IF(BE29>=2.5," 3 ",IF(BE29>=1.5," 2 ",IF(BE29>=1,"1 ",IF(BE29>=0,"0")))))) -> #DIV/0! | AH29: =AVERAGE(AC29:AG29) -> #DIV/0! | AN29: =AVERAGE(AI29:AM29) -> #DIV/0! | AT29: =AVERAGE(AO29:AS29) -> #DIV/0! | AW29: =IF(AU29>=85,"5",IF(AU29>=65,"4",IF(AU29>=55,"3",IF(AU29>=40,"2",IF(AU29>=1,"1",IF(AU29>="","0")))))) -> 0 | AX29: =IF(BJ29>=4.5, " 5 ", IF(BJ29>=3.5," 4 ",IF(BJ29>=2.5," 3 ",IF(BJ29>=1.5," 2 ",IF(BJ29>=1,"1 ",IF(BJ29>=0,"0")))))) -> #DIV/0! | AY29: =IF(BK29>=4.5, " 5 ", IF(BK29>=3.5," 4 ",IF(BK29>=2.5," 3 ",IF(BK29>=1.5," 2 ",IF(BK29>=1,"1 ",IF(BK29>=0,"0")))))) -> #DIV/0! | AZ29: =IF(BP29>=4.5, " 5 ", IF(BP29>=3.5," 4 ",IF(BP29>=2.5," 3 ",IF(BP29>=1.5," 2 ",IF(BP29>=1,"1 ",IF(BP29>=0,"0")))))) -> #DIV/0! | BA29: =$K29*$F$12 -> #DIV/0! | BB29: =$Q29*$L$12 -> #DIV/0! | BC29: =$W29*$R$12 -> #DIV/0! | BD29: =$Z29*$X$12 -> 0 | BE29: =BA29+BB29+BC29+BD29 -> #DIV/0! | BF29: =$AH29*$AC$12 -> #DIV/0! | BG29: =$AN29*$AI$12 -> #DIV/0! | BH29: =$AT29*$AO$12 -> #DIV/0! | BI29: =$AW29*$AU$12 -> 0 | BJ29: =(BF29+BG29+BH29+BI29) -> #DIV/0! | BK29: =(BE29+BJ29)/2 -> #DIV/0! | BL29: =(BE29+BJ29)/2 -> #DIV/0! | BM29: =ROUND(BL29,) -> #DIV/0! | BN29: =ROUND(BO30,) -> #DIV/0! | BP29: =(AY29+AY30)/2 -> #DIV/0!
E30: 2 | K30: =AVERAGE(F30:J30) -> #DIV/0! | Q30: =AVERAGE(L30:P30) -> #DIV/0! | W30: =AVERAGE(R30:V30) -> #DIV/0! | Z30: =IF(X30>=85,"5",IF(X30>=65,"4",IF(X30>=55,"3",IF(X30>=40,"2",IF(X30>=1,"1",IF(X30>="","0")))))) -> 0 | AA30: =IF(BE30>=4.5, " 5 ", IF(BE30>=3.5," 4 ",IF(BE30>=2.5," 3 ",IF(BE30>=1.5," 2 ",IF(BE30>=1,"1 ",IF(BE30>=0,"0")))))) -> #DIV/0! | AH30: =AVERAGE(AC30:AG30) -> #DIV/0! | AN30: =AVERAGE(AI30:AM30) -> #DIV/0! | AT30: =AVERAGE(AO30:AS30) -> #DIV/0! | AW30: =IF(AU30>=85,"5",IF(AU30>=65,"4",IF(AU30>=55,"3",IF(AU30>=40,"2",IF(AU30>=1,"1",IF(AU30>="","0")))))) -> 0 | AX30: =IF(BJ30>=4.5, " 5 ", IF(BJ30>=3.5," 4 ",IF(BJ30>=2.5," 3 ",IF(BJ30>=1.5," 2 ",IF(BJ30>=1,"1 ",IF(BJ30>=0,"0")))))) -> #DIV/0! | AY30: =IF(BK30>=4.5, " 5 ", IF(BK30>=3.5," 4 ",IF(BK30>=2.5," 3 ",IF(BK30>=1.5," 2 ",IF(BK30>=1,"1 ",IF(BK30>=0,"0")))))) -> #DIV/0! | BA30: =$K30*$F$12 -> #DIV/0! | BB30: =$Q30*$L$12 -> #DIV/0! | BC30: =$W30*$R$12 -> #DIV/0! | BD30: =$Z30*$X$12 -> 0 | BE30: =BA30+BB30+BC30+BD30 -> #DIV/0! | BF30: =$AH30*$AC$12 -> #DIV/0! | BG30: =$AN30*$AI$12 -> #DIV/0! | BH30: =$AT30*$AO$12 -> #DIV/0! | BI30: =$AW30*$AU$12 -> 0 | BJ30: =(BF30+BG30+BH30+BI30) -> #DIV/0! | BK30: =(BE30+BJ30)/2 -> #DIV/0! | BO30: =(BE30+BJ30)/2 -> #DIV/0!
A31: 10 | E31: 1 | K31: =AVERAGE(F31:J31) -> #DIV/0! | Q31: =AVERAGE(L31:P31) -> #DIV/0! | W31: =AVERAGE(R31:V31) -> #DIV/0! | Z31: =IF(X31>=85,"5",IF(X31>=65,"4",IF(X31>=55,"3",IF(X31>=40,"2",IF(X31>=1,"1",IF(X31>="","0")))))) -> 0 | AA31: =IF(BE31>=4.5, " 5 ", IF(BE31>=3.5," 4 ",IF(BE31>=2.5," 3 ",IF(BE31>=1.5," 2 ",IF(BE31>=1,"1 ",IF(BE31>=0,"0")))))) -> #DIV/0! | AH31: =AVERAGE(AC31:AG31) -> #DIV/0! | AN31: =AVERAGE(AI31:AM31) -> #DIV/0! | AT31: =AVERAGE(AO31:AS31) -> #DIV/0! | AW31: =IF(AU31>=85,"5",IF(AU31>=65,"4",IF(AU31>=55,"3",IF(AU31>=40,"2",IF(AU31>=1,"1",IF(AU31>="","0")))))) -> 0 | AX31: =IF(BJ31>=4.5, " 5 ", IF(BJ31>=3.5," 4 ",IF(BJ31>=2.5," 3 ",IF(BJ31>=1.5," 2 ",IF(BJ31>=1,"1 ",IF(BJ31>=0,"0")))))) -> #DIV/0! | AY31: =IF(BK31>=4.5, " 5 ", IF(BK31>=3.5," 4 ",IF(BK31>=2.5," 3 ",IF(BK31>=1.5," 2 ",IF(BK31>=1,"1 ",IF(BK31>=0,"0")))))) -> #DIV/0! | AZ31: =IF(BP31>=4.5, " 5 ", IF(BP31>=3.5," 4 ",IF(BP31>=2.5," 3 ",IF(BP31>=1.5," 2 ",IF(BP31>=1,"1 ",IF(BP31>=0,"0")))))) -> #DIV/0! | BA31: =$K31*$F$12 -> #DIV/0! | BB31: =$Q31*$L$12 -> #DIV/0! | BC31: =$W31*$R$12 -> #DIV/0! | BD31: =$Z31*$X$12 -> 0 | BE31: =BA31+BB31+BC31+BD31 -> #DIV/0! | BF31: =$AH31*$AC$12 -> #DIV/0! | BG31: =$AN31*$AI$12 -> #DIV/0! | BH31: =$AT31*$AO$12 -> #DIV/0! | BI31: =$AW31*$AU$12 -> 0 | BJ31: =(BF31+BG31+BH31+BI31) -> #DIV/0! | BK31: =(BE31+BJ31)/2 -> #DIV/0! | BL31: =(BE31+BJ31)/2 -> #DIV/0! | BM31: =ROUND(BL31,) -> #DIV/0! | BN31: =ROUND(BO32,) -> #DIV/0! | BP31: =(AY31+AY32)/2 -> #DIV/0!
E32: 2 | K32: =AVERAGE(F32:J32) -> #DIV/0! | Q32: =AVERAGE(L32:P32) -> #DIV/0! | W32: =AVERAGE(R32:V32) -> #DIV/0! | Z32: =IF(X32>=85,"5",IF(X32>=65,"4",IF(X32>=55,"3",IF(X32>=40,"2",IF(X32>=1,"1",IF(X32>="","0")))))) -> 0 | AA32: =IF(BE32>=4.5, " 5 ", IF(BE32>=3.5," 4 ",IF(BE32>=2.5," 3 ",IF(BE32>=1.5," 2 ",IF(BE32>=1,"1 ",IF(BE32>=0,"0")))))) -> #DIV/0! | AH32: =AVERAGE(AC32:AG32) -> #DIV/0! | AN32: =AVERAGE(AI32:AM32) -> #DIV/0! | AT32: =AVERAGE(AO32:AS32) -> #DIV/0! | AW32: =IF(AU32>=85,"5",IF(AU32>=65,"4",IF(AU32>=55,"3",IF(AU32>=40,"2",IF(AU32>=1,"1",IF(AU32>="","0")))))) -> 0 | AX32: =IF(BJ32>=4.5, " 5 ", IF(BJ32>=3.5," 4 ",IF(BJ32>=2.5," 3 ",IF(BJ32>=1.5," 2 ",IF(BJ32>=1,"1 ",IF(BJ32>=0,"0")))))) -> #DIV/0! | AY32: =IF(BK32>=4.5, " 5 ", IF(BK32>=3.5," 4 ",IF(BK32>=2.5," 3 ",IF(BK32>=1.5," 2 ",IF(BK32>=1,"1 ",IF(BK32>=0,"0")))))) -> #DIV/0! | BA32: =$K32*$F$12 -> #DIV/0! | BB32: =$Q32*$L$12 -> #DIV/0! | BC32: =$W32*$R$12 -> #DIV/0! | BD32: =$Z32*$X$12 -> 0 | BE32: =BA32+BB32+BC32+BD32 -> #DIV/0! | BF32: =$AH32*$AC$12 -> #DIV/0! | BG32: =$AN32*$AI$12 -> #DIV/0! | BH32: =$AT32*$AO$12 -> #DIV/0! | BI32: =$AW32*$AU$12 -> 0 | BJ32: =(BF32+BG32+BH32+BI32) -> #DIV/0! | BK32: =(BE32+BJ32)/2 -> #DIV/0! | BO32: =(BE32+BJ32)/2 -> #DIV/0!
A33: 11 | E33: 1 | K33: =AVERAGE(F33:J33) -> #DIV/0! | Q33: =AVERAGE(L33:P33) -> #DIV/0! | W33: =AVERAGE(R33:V33) -> #DIV/0! | Z33: =IF(X33>=85,"5",IF(X33>=65,"4",IF(X33>=55,"3",IF(X33>=40,"2",IF(X33>=1,"1",IF(X33>="","0")))))) -> 0 | AA33: =IF(BE33>=4.5, " 5 ", IF(BE33>=3.5," 4 ",IF(BE33>=2.5," 3 ",IF(BE33>=1.5," 2 ",IF(BE33>=1,"1 ",IF(BE33>=0,"0")))))) -> #DIV/0! | AH33: =AVERAGE(AC33:AG33) -> #DIV/0! | AN33: =AVERAGE(AI33:AM33) -> #DIV/0! | AT33: =AVERAGE(AO33:AS33) -> #DIV/0! | AW33: =IF(AU33>=85,"5",IF(AU33>=65,"4",IF(AU33>=55,"3",IF(AU33>=40,"2",IF(AU33>=1,"1",IF(AU33>="","0")))))) -> 0 | AX33: =IF(BJ33>=4.5, " 5 ", IF(BJ33>=3.5," 4 ",IF(BJ33>=2.5," 3 ",IF(BJ33>=1.5," 2 ",IF(BJ33>=1,"1 ",IF(BJ33>=0,"0")))))) -> #DIV/0! | AY33: =IF(BK33>=4.5, " 5 ", IF(BK33>=3.5," 4 ",IF(BK33>=2.5," 3 ",IF(BK33>=1.5," 2 ",IF(BK33>=1,"1 ",IF(BK33>=0,"0")))))) -> #DIV/0! | AZ33: =IF(BP33>=4.5, " 5 ", IF(BP33>=3.5," 4 ",IF(BP33>=2.5," 3 ",IF(BP33>=1.5," 2 ",IF(BP33>=1,"1 ",IF(BP33>=0,"0")))))) -> #DIV/0! | BA33: =$K33*$F$12 -> #DIV/0! | BB33: =$Q33*$L$12 -> #DIV/0! | BC33: =$W33*$R$12 -> #DIV/0! | BD33: =$Z33*$X$12 -> 0 | BE33: =BA33+BB33+BC33+BD33 -> #DIV/0! | BF33: =$AH33*$AC$12 -> #DIV/0! | BG33: =$AN33*$AI$12 -> #DIV/0! | BH33: =$AT33*$AO$12 -> #DIV/0! | BI33: =$AW33*$AU$12 -> 0 | BJ33: =(BF33+BG33+BH33+BI33) -> #DIV/0! | BK33: =(BE33+BJ33)/2 -> #DIV/0! | BL33: =(BE33+BJ33)/2 -> #DIV/0! | BM33: =ROUND(BL33,) -> #DIV/0! | BN33: =ROUND(BO34,) -> #DIV/0! | BP33: =(AY33+AY34)/2 -> #DIV/0!
E34: 2 | K34: =AVERAGE(F34:J34) -> #DIV/0! | Q34: =AVERAGE(L34:P34) -> #DIV/0! | W34: =AVERAGE(R34:V34) -> #DIV/0! | Z34: =IF(X34>=85,"5",IF(X34>=65,"4",IF(X34>=55,"3",IF(X34>=40,"2",IF(X34>=1,"1",IF(X34>="","0")))))) -> 0 | AA34: =IF(BE34>=4.5, " 5 ", IF(BE34>=3.5," 4 ",IF(BE34>=2.5," 3 ",IF(BE34>=1.5," 2 ",IF(BE34>=1,"1 ",IF(BE34>=0,"0")))))) -> #DIV/0! | AH34: =AVERAGE(AC34:AG34) -> #DIV/0! | AN34: =AVERAGE(AI34:AM34) -> #DIV/0! | AT34: =AVERAGE(AO34:AS34) -> #DIV/0! | AW34: =IF(AU34>=85,"5",IF(AU34>=65,"4",IF(AU34>=55,"3",IF(AU34>=40,"2",IF(AU34>=1,"1",IF(AU34>="","0")))))) -> 0 | AX34: =IF(BJ34>=4.5, " 5 ", IF(BJ34>=3.5," 4 ",IF(BJ34>=2.5," 3 ",IF(BJ34>=1.5," 2 ",IF(BJ34>=1,"1 ",IF(BJ34>=0,"0")))))) -> #DIV/0! | AY34: =IF(BK34>=4.5, " 5 ", IF(BK34>=3.5," 4 ",IF(BK34>=2.5," 3 ",IF(BK34>=1.5," 2 ",IF(BK34>=1,"1 ",IF(BK34>=0,"0")))))) -> #DIV/0! | BA34: =$K34*$F$12 -> #DIV/0! | BB34: =$Q34*$L$12 -> #DIV/0! | BC34: =$W34*$R$12 -> #DIV/0! | BD34: =$Z34*$X$12 -> 0 | BE34: =BA34+BB34+BC34+BD34 -> #DIV/0! | BF34: =$AH34*$AC$12 -> #DIV/0! | BG34: =$AN34*$AI$12 -> #DIV/0! | BH34: =$AT34*$AO$12 -> #DIV/0! | BI34: =$AW34*$AU$12 -> 0 | BJ34: =(BF34+BG34+BH34+BI34) -> #DIV/0! | BK34: =(BE34+BJ34)/2 -> #DIV/0! | BO34: =(BE34+BJ34)/2 -> #DIV/0!
A35: 12 | E35: 1 | K35: =AVERAGE(F35:J35) -> #DIV/0! | Q35: =AVERAGE(L35:P35) -> #DIV/0! | W35: =AVERAGE(R35:V35) -> #DIV/0! | Z35: =IF(X35>=85,"5",IF(X35>=65,"4",IF(X35>=55,"3",IF(X35>=40,"2",IF(X35>=1,"1",IF(X35>="","0")))))) -> 0 | AA35: =IF(BE35>=4.5, " 5 ", IF(BE35>=3.5," 4 ",IF(BE35>=2.5," 3 ",IF(BE35>=1.5," 2 ",IF(BE35>=1,"1 ",IF(BE35>=0,"0")))))) -> #DIV/0! | AH35: =AVERAGE(AC35:AG35) -> #DIV/0! | AN35: =AVERAGE(AI35:AM35) -> #DIV/0! | AT35: =AVERAGE(AO35:AS35) -> #DIV/0! | AW35: =IF(AU35>=85,"5",IF(AU35>=65,"4",IF(AU35>=55,"3",IF(AU35>=40,"2",IF(AU35>=1,"1",IF(AU35>="","0")))))) -> 0 | AX35: =IF(BJ35>=4.5, " 5 ", IF(BJ35>=3.5," 4 ",IF(BJ35>=2.5," 3 ",IF(BJ35>=1.5," 2 ",IF(BJ35>=1,"1 ",IF(BJ35>=0,"0")))))) -> #DIV/0! | AY35: =IF(BK35>=4.5, " 5 ", IF(BK35>=3.5," 4 ",IF(BK35>=2.5," 3 ",IF(BK35>=1.5," 2 ",IF(BK35>=1,"1 ",IF(BK35>=0,"0")))))) -> #DIV/0! | AZ35: =IF(BP35>=4.5, " 5 ", IF(BP35>=3.5," 4 ",IF(BP35>=2.5," 3 ",IF(BP35>=1.5," 2 ",IF(BP35>=1,"1 ",IF(BP35>=0,"0")))))) -> #DIV/0! | BA35: =$K35*$F$12 -> #DIV/0! | BB35: =$Q35*$L$12 -> #DIV/0! | BC35: =$W35*$R$12 -> #DIV/0! | BD35: =$Z35*$X$12 -> 0 | BE35: =BA35+BB35+BC35+BD35 -> #DIV/0! | BF35: =$AH35*$AC$12 -> #DIV/0! | BG35: =$AN35*$AI$12 -> #DIV/0! | BH35: =$AT35*$AO$12 -> #DIV/0! | BI35: =$AW35*$AU$12 -> 0 | BJ35: =(BF35+BG35+BH35+BI35) -> #DIV/0! | BK35: =(BE35+BJ35)/2 -> #DIV/0! | BL35: =(BE35+BJ35)/2 -> #DIV/0! | BM35: =ROUND(BL35,) -> #DIV/0! | BN35: =ROUND(BO36,) -> #DIV/0! | BP35: =(AY35+AY36)/2 -> #DIV/0!
E36: 2 | K36: =AVERAGE(F36:J36) -> #DIV/0! | Q36: =AVERAGE(L36:P36) -> #DIV/0! | W36: =AVERAGE(R36:V36) -> #DIV/0! | Z36: =IF(X36>=85,"5",IF(X36>=65,"4",IF(X36>=55,"3",IF(X36>=40,"2",IF(X36>=1,"1",IF(X36>="","0")))))) -> 0 | AA36: =IF(BE36>=4.5, " 5 ", IF(BE36>=3.5," 4 ",IF(BE36>=2.5," 3 ",IF(BE36>=1.5," 2 ",IF(BE36>=1,"1 ",IF(BE36>=0,"0")))))) -> #DIV/0! | AH36: =AVERAGE(AC36:AG36) -> #DIV/0! | AN36: =AVERAGE(AI36:AM36) -> #DIV/0! | AT36: =AVERAGE(AO36:AS36) -> #DIV/0! | AW36: =IF(AU36>=85,"5",IF(AU36>=65,"4",IF(AU36>=55,"3",IF(AU36>=40,"2",IF(AU36>=1,"1",IF(AU36>="","0")))))) -> 0 | AX36: =IF(BJ36>=4.5, " 5 ", IF(BJ36>=3.5," 4 ",IF(BJ36>=2.5," 3 ",IF(BJ36>=1.5," 2 ",IF(BJ36>=1,"1 ",IF(BJ36>=0,"0")))))) -> #DIV/0! | AY36: =IF(BK36>=4.5, " 5 ", IF(BK36>=3.5," 4 ",IF(BK36>=2.5," 3 ",IF(BK36>=1.5," 2 ",IF(BK36>=1,"1 ",IF(BK36>=0,"0")))))) -> #DIV/0! | BA36: =$K36*$F$12 -> #DIV/0! | BB36: =$Q36*$L$12 -> #DIV/0! | BC36: =$W36*$R$12 -> #DIV/0! | BD36: =$Z36*$X$12 -> 0 | BE36: =BA36+BB36+BC36+BD36 -> #DIV/0! | BF36: =$AH36*$AC$12 -> #DIV/0! | BG36: =$AN36*$AI$12 -> #DIV/0! | BH36: =$AT36*$AO$12 -> #DIV/0! | BI36: =$AW36*$AU$12 -> 0 | BJ36: =(BF36+BG36+BH36+BI36) -> #DIV/0! | BK36: =(BE36+BJ36)/2 -> #DIV/0! | BO36: =(BE36+BJ36)/2 -> #DIV/0!
A37: 13 | E37: 1 | K37: =AVERAGE(F37:J37) -> #DIV/0! | Q37: =AVERAGE(L37:P37) -> #DIV/0! | W37: =AVERAGE(R37:V37) -> #DIV/0! | Z37: =IF(X37>=85,"5",IF(X37>=65,"4",IF(X37>=55,"3",IF(X37>=40,"2",IF(X37>=1,"1",IF(X37>="","0")))))) -> 0 | AA37: =IF(BE37>=4.5, " 5 ", IF(BE37>=3.5," 4 ",IF(BE37>=2.5," 3 ",IF(BE37>=1.5," 2 ",IF(BE37>=1,"1 ",IF(BE37>=0,"0")))))) -> #DIV/0! | AH37: =AVERAGE(AC37:AG37) -> #DIV/0! | AN37: =AVERAGE(AI37:AM37) -> #DIV/0! | AT37: =AVERAGE(AO37:AS37) -> #DIV/0! | AW37: =IF(AU37>=85,"5",IF(AU37>=65,"4",IF(AU37>=55,"3",IF(AU37>=40,"2",IF(AU37>=1,"1",IF(AU37>="","0")))))) -> 0 | AX37: =IF(BJ37>=4.5, " 5 ", IF(BJ37>=3.5," 4 ",IF(BJ37>=2.5," 3 ",IF(BJ37>=1.5," 2 ",IF(BJ37>=1,"1 ",IF(BJ37>=0,"0")))))) -> #DIV/0! | AY37: =IF(BK37>=4.5, " 5 ", IF(BK37>=3.5," 4 ",IF(BK37>=2.5," 3 ",IF(BK37>=1.5," 2 ",IF(BK37>=1,"1 ",IF(BK37>=0,"0")))))) -> #DIV/0! | AZ37: =IF(BP37>=4.5, " 5 ", IF(BP37>=3.5," 4 ",IF(BP37>=2.5," 3 ",IF(BP37>=1.5," 2 ",IF(BP37>=1,"1 ",IF(BP37>=0,"0")))))) -> #DIV/0! | BA37: =$K37*$F$12 -> #DIV/0! | BB37: =$Q37*$L$12 -> #DIV/0! | BC37: =$W37*$R$12 -> #DIV/0! | BD37: =$Z37*$X$12 -> 0 | BE37: =BA37+BB37+BC37+BD37 -> #DIV/0! | BF37: =$AH37*$AC$12 -> #DIV/0! | BG37: =$AN37*$AI$12 -> #DIV/0! | BH37: =$AT37*$AO$12 -> #DIV/0! | BI37: =$AW37*$AU$12 -> 0 | BJ37: =(BF37+BG37+BH37+BI37) -> #DIV/0! | BK37: =(BE37+BJ37)/2 -> #DIV/0! | BL37: =(BE37+BJ37)/2 -> #DIV/0! | BM37: =ROUND(BL37,) -> #DIV/0! | BN37: =ROUND(BO38,) -> #DIV/0! | BP37: =(AY37+AY38)/2 -> #DIV/0!
E38: 2 | K38: =AVERAGE(F38:J38) -> #DIV/0! | Q38: =AVERAGE(L38:P38) -> #DIV/0! | W38: =AVERAGE(R38:V38) -> #DIV/0! | Z38: =IF(X38>=85,"5",IF(X38>=65,"4",IF(X38>=55,"3",IF(X38>=40,"2",IF(X38>=1,"1",IF(X38>="","0")))))) -> 0 | AA38: =IF(BE38>=4.5, " 5 ", IF(BE38>=3.5," 4 ",IF(BE38>=2.5," 3 ",IF(BE38>=1.5," 2 ",IF(BE38>=1,"1 ",IF(BE38>=0,"0")))))) -> #DIV/0! | AH38: =AVERAGE(AC38:AG38) -> #DIV/0! | AN38: =AVERAGE(AI38:AM38) -> #DIV/0! | AT38: =AVERAGE(AO38:AS38) -> #DIV/0! | AW38: =IF(AU38>=85,"5",IF(AU38>=65,"4",IF(AU38>=55,"3",IF(AU38>=40,"2",IF(AU38>=1,"1",IF(AU38>="","0")))))) -> 0 | AX38: =IF(BJ38>=4.5, " 5 ", IF(BJ38>=3.5," 4 ",IF(BJ38>=2.5," 3 ",IF(BJ38>=1.5," 2 ",IF(BJ38>=1,"1 ",IF(BJ38>=0,"0")))))) -> #DIV/0! | AY38: =IF(BK38>=4.5, " 5 ", IF(BK38>=3.5," 4 ",IF(BK38>=2.5," 3 ",IF(BK38>=1.5," 2 ",IF(BK38>=1,"1 ",IF(BK38>=0,"0")))))) -> #DIV/0! | BA38: =$K38*$F$12 -> #DIV/0! | BB38: =$Q38*$L$12 -> #DIV/0! | BC38: =$W38*$R$12 -> #DIV/0! | BD38: =$Z38*$X$12 -> 0 | BE38: =BA38+BB38+BC38+BD38 -> #DIV/0! | BF38: =$AH38*$AC$12 -> #DIV/0! | BG38: =$AN38*$AI$12 -> #DIV/0! | BH38: =$AT38*$AO$12 -> #DIV/0! | BI38: =$AW38*$AU$12 -> 0 | BJ38: =(BF38+BG38+BH38+BI38) -> #DIV/0! | BK38: =(BE38+BJ38)/2 -> #DIV/0! | BO38: =(BE38+BJ38)/2 -> #DIV/0!
A39: 14 | E39: 1 | K39: =AVERAGE(F39:J39) -> #DIV/0! | Q39: =AVERAGE(L39:P39) -> #DIV/0! | W39: =AVERAGE(R39:V39) -> #DIV/0! | Z39: =IF(X39>=85,"5",IF(X39>=65,"4",IF(X39>=55,"3",IF(X39>=40,"2",IF(X39>=1,"1",IF(X39>="","0")))))) -> 0 | AA39: =IF(BE39>=4.5, " 5 ", IF(BE39>=3.5," 4 ",IF(BE39>=2.5," 3 ",IF(BE39>=1.5," 2 ",IF(BE39>=1,"1 ",IF(BE39>=0,"0")))))) -> #DIV/0! | AH39: =AVERAGE(AC39:AG39) -> #DIV/0! | AN39: =AVERAGE(AI39:AM39) -> #DIV/0! | AT39: =AVERAGE(AO39:AS39) -> #DIV/0! | AW39: =IF(AU39>=85,"5",IF(AU39>=65,"4",IF(AU39>=55,"3",IF(AU39>=40,"2",IF(AU39>=1,"1",IF(AU39>="","0")))))) -> 0 | AX39: =IF(BJ39>=4.5, " 5 ", IF(BJ39>=3.5," 4 ",IF(BJ39>=2.5," 3 ",IF(BJ39>=1.5," 2 ",IF(BJ39>=1,"1 ",IF(BJ39>=0,"0")))))) -> #DIV/0! | AY39: =IF(BK39>=4.5, " 5 ", IF(BK39>=3.5," 4 ",IF(BK39>=2.5," 3 ",IF(BK39>=1.5," 2 ",IF(BK39>=1,"1 ",IF(BK39>=0,"0")))))) -> #DIV/0! | AZ39: =IF(BP39>=4.5, " 5 ", IF(BP39>=3.5," 4 ",IF(BP39>=2.5," 3 ",IF(BP39>=1.5," 2 ",IF(BP39>=1,"1 ",IF(BP39>=0,"0")))))) -> #DIV/0! | BA39: =$K39*$F$12 -> #DIV/0! | BB39: =$Q39*$L$12 -> #DIV/0! | BC39: =$W39*$R$12 -> #DIV/0! | BD39: =$Z39*$X$12 -> 0 | BE39: =BA39+BB39+BC39+BD39 -> #DIV/0! | BF39: =$AH39*$AC$12 -> #DIV/0! | BG39: =$AN39*$AI$12 -> #DIV/0! | BH39: =$AT39*$AO$12 -> #DIV/0! | BI39: =$AW39*$AU$12 -> 0 | BJ39: =(BF39+BG39+BH39+BI39) -> #DIV/0! | BK39: =(BE39+BJ39)/2 -> #DIV/0! | BL39: =(BE39+BJ39)/2 -> #DIV/0! | BM39: =ROUND(BL39,) -> #DIV/0! | BN39: =ROUND(BO40,) -> #DIV/0! | BP39: =(AY39+AY40)/2 -> #DIV/0!
E40: 2 | K40: =AVERAGE(F40:J40) -> #DIV/0! | Q40: =AVERAGE(L40:P40) -> #DIV/0! | W40: =AVERAGE(R40:V40) -> #DIV/0! | Z40: =IF(X40>=85,"5",IF(X40>=65,"4",IF(X40>=55,"3",IF(X40>=40,"2",IF(X40>=1,"1",IF(X40>="","0")))))) -> 0 | AA40: =IF(BE40>=4.5, " 5 ", IF(BE40>=3.5," 4 ",IF(BE40>=2.5," 3 ",IF(BE40>=1.5," 2 ",IF(BE40>=1,"1 ",IF(BE40>=0,"0")))))) -> #DIV/0! | AH40: =AVERAGE(AC40:AG40) -> #DIV/0! | AN40: =AVERAGE(AI40:AM40) -> #DIV/0! | AT40: =AVERAGE(AO40:AS40) -> #DIV/0! | AW40: =IF(AU40>=85,"5",IF(AU40>=65,"4",IF(AU40>=55,"3",IF(AU40>=40,"2",IF(AU40>=1,"1",IF(AU40>="","0")))))) -> 0 | AX40: =IF(BJ40>=4.5, " 5 ", IF(BJ40>=3.5," 4 ",IF(BJ40>=2.5," 3 ",IF(BJ40>=1.5," 2 ",IF(BJ40>=1,"1 ",IF(BJ40>=0,"0")))))) -> #DIV/0! | AY40: =IF(BK40>=4.5, " 5 ", IF(BK40>=3.5," 4 ",IF(BK40>=2.5," 3 ",IF(BK40>=1.5," 2 ",IF(BK40>=1,"1 ",IF(BK40>=0,"0")))))) -> #DIV/0! | BA40: =$K40*$F$12 -> #DIV/0! | BB40: =$Q40*$L$12 -> #DIV/0! | BC40: =$W40*$R$12 -> #DIV/0! | BD40: =$Z40*$X$12 -> 0 | BE40: =BA40+BB40+BC40+BD40 -> #DIV/0! | BF40: =$AH40*$AC$12 -> #DIV/0! | BG40: =$AN40*$AI$12 -> #DIV/0! | BH40: =$AT40*$AO$12 -> #DIV/0! | BI40: =$AW40*$AU$12 -> 0 | BJ40: =(BF40+BG40+BH40+BI40) -> #DIV/0! | BK40: =(BE40+BJ40)/2 -> #DIV/0! | BO40: =(BE40+BJ40)/2 -> #DIV/0!
A41: 15 | E41: 1 | K41: =AVERAGE(F41:J41) -> #DIV/0! | Q41: =AVERAGE(L41:P41) -> #DIV/0! | W41: =AVERAGE(R41:V41) -> #DIV/0! | Z41: =IF(X41>=85,"5",IF(X41>=65,"4",IF(X41>=55,"3",IF(X41>=40,"2",IF(X41>=1,"1",IF(X41>="","0")))))) -> 0 | AA41: =IF(BE41>=4.5, " 5 ", IF(BE41>=3.5," 4 ",IF(BE41>=2.5," 3 ",IF(BE41>=1.5," 2 ",IF(BE41>=1,"1 ",IF(BE41>=0,"0")))))) -> #DIV/0! | AH41: =AVERAGE(AC41:AG41) -> #DIV/0! | AN41: =AVERAGE(AI41:AM41) -> #DIV/0! | AT41: =AVERAGE(AO41:AS41) -> #DIV/0! | AW41: =IF(AU41>=85,"5",IF(AU41>=65,"4",IF(AU41>=55,"3",IF(AU41>=40,"2",IF(AU41>=1,"1",IF(AU41>="","0")))))) -> 0 | AX41: =IF(BJ41>=4.5, " 5 ", IF(BJ41>=3.5," 4 ",IF(BJ41>=2.5," 3 ",IF(BJ41>=1.5," 2 ",IF(BJ41>=1,"1 ",IF(BJ41>=0,"0")))))) -> #DIV/0! | AY41: =IF(BK41>=4.5, " 5 ", IF(BK41>=3.5," 4 ",IF(BK41>=2.5," 3 ",IF(BK41>=1.5," 2 ",IF(BK41>=1,"1 ",IF(BK41>=0,"0")))))) -> #DIV/0! | AZ41: =IF(BP41>=4.5, " 5 ", IF(BP41>=3.5," 4 ",IF(BP41>=2.5," 3 ",IF(BP41>=1.5," 2 ",IF(BP41>=1,"1 ",IF(BP41>=0,"0")))))) -> #DIV/0! | BA41: =$K41*$F$12 -> #DIV/0! | BB41: =$Q41*$L$12 -> #DIV/0! | BC41: =$W41*$R$12 -> #DIV/0! | BD41: =$Z41*$X$12 -> 0 | BE41: =BA41+BB41+BC41+BD41 -> #DIV/0! | BF41: =$AH41*$AC$12 -> #DIV/0! | BG41: =$AN41*$AI$12 -> #DIV/0! | BH41: =$AT41*$AO$12 -> #DIV/0! | BI41: =$AW41*$AU$12 -> 0 | BJ41: =(BF41+BG41+BH41+BI41) -> #DIV/0! | BK41: =(BE41+BJ41)/2 -> #DIV/0! | BL41: =(BE41+BJ41)/2 -> #DIV/0! | BM41: =ROUND(BL41,) -> #DIV/0! | BN41: =ROUND(BO42,) -> #DIV/0! | BP41: =(AY41+AY42)/2 -> #DIV/0!
...

Sheet 6-2
A1: Punoi Naser A. Guri | B1: SHFMU "EMIN DURAKU" KAÇANIK | S1: Gjysmëvjetori | Y1: i parë, | AG1: i dytë, | AR1: Suksesi përfundimtar
D2: Viti shkollor: | I2: 2023/2024 | M2: Klasa: | P2: VI-2 | S2: Suksesi | X2: Nr. | Z2: % | AB2: M | AC2: F | AD2: gjithsej | AG2: Nr. | AI2: % | AK2: M | AM2: F | AO2: gjithsej | AR2: Nr. | AT2: % | AV2: M | AW2: F | AY2: Gjithsej | BE2: NOTA 1 | BJ2: NOTA 2 | BK2: NOTA 1&2 | BL2: GJYSMËVJETORI I | BM2: GJYSMËVJETORI I | BN2: GJYSMËVJETORI II | BO2: GJYSMËVJETORI II | BP2: PËRFUNDIMTARI
S3: shkëlq | X3: =COUNTIF($BM$13:$BM$72,"5") -> 0 | Z3: =X3/$AD$3 -> #DIV/0! | AB3: =COUNTIFS($BM$13:$BM$72,"5",$D$13:$D$72,"M") -> 0 | AC3: =COUNTIFS($BM$13:$BM$72,"5",$D$13:$D$72,"F") -> 0 | AD3: =SUM(X3:Y7) -> 0 | AG3: =COUNTIF($BN$13:$BN$71,"5") -> 0 | AI3: =AG3/$AO$3 -> #DIV/0! | AK3: =COUNTIFS($BN$13:$BN$72,"5",$D$13:$D$72,"M") -> 0 | AM3: =COUNTIFS($BN$13:$BN$72,"5",$D$13:$D$72,"F") -> 0 | AO3: =SUM(AG3:AH7) -> 0 | AR3: =COUNTIF($AZ$13:$AZ$72,"5") -> 0 | AT3: =AR3/$AY$3 -> #DIV/0! | AV3: =COUNTIFS($AZ$13:$AZ$72,"5",$D$13:$D$72,"M") -> 0 | AW3: =COUNTIFS($AZ$13:$AZ$72,"5",$D$13:$D$72,"f") -> 0 | AY3: =SUM(AR3:AS7) -> 0
D4: Fusha kurrikulare | S4: sh.mirë | X4: =COUNTIF($BM$13:$BM$72,"4") -> 0 | Z4: =X4/$AD$3 -> #DIV/0! | AB4: =COUNTIFS($BM$13:$BM$72,"4",$D$13:$D$72,"M") -> 0 | AC4: =COUNTIFS($BM$13:$BM$72,"4",$D$13:$D$72,"F") -> 0 | AD4: Kalojnë | AG4: =COUNTIF($BN$13:$BN$71,"4") -> 0 | AI4: =AG4/$AO$3 -> #DIV/0! | AK4: =COUNTIFS($BN$13:$BN$72,"4",$D$13:$D$72,"M") -> 0 | AM4: =COUNTIFS($BN$13:$BN$72,"4",$D$13:$D$72,"F") -> 0 | AO4: Kalojnë | AR4: =COUNTIF($AZ$13:$AZ$72,"4") -> 0 | AT4: =AR4/$AY$3 -> #DIV/0! | AV4: =COUNTIFS($AZ$13:$AZ$72,"4",$D$13:$D$72,"M") -> 0 | AW4: =COUNTIFS($AZ$13:$AZ$72,"4",$D$13:$D$72,"F") -> 0 | AY4: Kalojnë
D5: Shkencat e natyrës | S5: mirë | X5: =COUNTIF($BM$13:$BM$72,"3") -> 0 | Z5: =X5/$AD$3 -> #DIV/0! | AB5: =COUNTIFS($BM$13:$BM$72,"3",$D$13:$D$72,"M") -> 0 | AC5: =COUNTIFS($BM$13:$BM$72,"3",$D$13:$D$72,"F") -> 0 | AD5: =SUM(X3:Y6) -> 0 | AG5: =COUNTIF($BN$13:$BN$71,"3") -> 0 | AI5: =AG5/$AO$3 -> #DIV/0! | AK5: =COUNTIFS($BN$13:$BN$72,"3",$D$13:$D$72,"M") -> 0 | AM5: =COUNTIFS($BN$13:$BN$72,"3",$D$13:$D$72,"F") -> 0 | AO5: =SUM(AG3:AH6) -> 0 | AR5: =COUNTIF($AZ$13:$AZ$72,"3") -> 0 | AT5: =AR5/$AY$3 -> #DIV/0! | AV5: =COUNTIFS($AZ$13:$AZ$72,"3",$D$13:$D$72,"M") -> 0 | AW5: =COUNTIFS($AZ$13:$AZ$72,"3",$D$13:$D$72,"F") -> 0 | AY5: =SUM(AQ3:AR6) -> 0
A6: Lënda: | D6: Biologji | S6: mjaft | X6: =COUNTIF($BM$13:$BM$72,"2") -> 0 | Z6: =X6/$AD$3 -> #DIV/0! | AB6: =COUNTIFS($BM$13:$BM$72,"2",$D$13:$D$72,"M") -> 0 | AC6: =COUNTIFS($BM$13:$BM$72,"2",$D$13:$D$72,"F") -> 0 | AD6: Mbesin | AG6: =COUNTIF($BN$13:$BN$71,"2") -> 0 | AI6: =AG6/$AO$3 -> #DIV/0! | AK6: =COUNTIFS($BN$13:$BN$72,"2",$D$13:$D$72,"M") -> 0 | AM6: =COUNTIFS($BN$13:$BN$72,"2",$D$13:$D$72,"F") -> 0 | AO6: Mbesin | AR6: =COUNTIF($AZ$13:$AZ$72,"2") -> 0 | AT6: =AR6/$AY$3 -> #DIV/0! | AV6: =COUNTIFS($AZ$13:$AZ$72,"2",$D$13:$D$72,"M") -> 0 | AW6: =COUNTIFS($AZ$13:$AZ$72,"2",$D$13:$D$72,"F") -> 0 | AY6: Mbesin
S7: pamjaft | X7: =COUNTIF($BM$13:$BM$72,"1") -> 0 | Z7: =X7/$AD$3 -> #DIV/0! | AB7: =COUNTIFS($BM$13:$BM$72,"1",$D$13:$D$72,"M") -> 0 | AC7: =COUNTIFS($BM$13:$BM$72,"1",$D$13:$D$72,"F") -> 0 | AD7: =X7 -> 0 | AG7: =COUNTIF($BN$13:$BN$71,"1") -> 0 | AI7: =AG7/$AO$3 -> #DIV/0! | AK7: =COUNTIFS($BN$13:$BN$72,"1",$D$13:$D$72,"M") -> 0 | AM7: =COUNTIFS($BN$13:$BN$72,"1",$D$13:$D$72,"F") -> 0 | AO7: =AG7 -> 0 | AR7: =COUNTIF($AZ$13:$AZ$72,"1") -> 0 | AT7: =AR7/$AY$3 -> #DIV/0! | AV7: =COUNTIFS($AZ$13:$AZ$72,"1",$D$13:$D$72,"M") -> 0 | AW7: =COUNTIFS($AZ$13:$AZ$72,"1",$D$13:$D$72,"F") -> 0 | AY7: =AR7 -> 0
A8: Mësimdhënësi-ja | D8: Naser Guri | S8: Nota mesatare GJ1 | AD8: =AVERAGEIF(BL13:BL72,">=1") -> #DIV/0! | AG8: GJ2 | AO8: =AVERAGEIF(BN13:BN72,">=1") -> #DIV/0! | AR8: Nota përfundimtare | AY8: =AVERAGEIF(BK13:BK72,">=1") -> #DIV/0!
A9: Instrumentet e vlerësimit | D9: Gjinia | E9: Gjysmëvjetori | F9: Angazhim në klasë | K9: Nota | L9: Detyra shtëpie | Q9: Nota | R9: Projekte & prezentime | W9: Nota | X9: Test | Z9: Nota | AA9: Nota 1 | AB9: Përfundim i vlerësimit 1 në anën e majtë dhe fillimi i vlerësimit përmbledhës 2 në anën e djathtë të tbelarit | AC9: Angazhim në klasë | AH9: Nota | AI9: Detyra shtëpie | AN9: Nota | AO9: Projekte & prezentime | AT9: Nota | AU9: Test | AW9: Nota | AX9: Nota 2 | AY9: Nota 1&2 | AZ9: Suksesi Përfundimtar
A11: Nr | B11: EMRAT DHE MBIEMRAT E NXËNËSVE
F12: 0.25 | L12: 0.15 | R12: 0.3 | X12: 0.3 | AA12: =F12+L12+R12+X12 -> 1 | AC12: 0.25 | AI12: 0.15 | AO12: 0.3 | AU12: 0.3 | AX12: =AC12+AI12+AO12+AU12 -> 1
A13: 1 | E13: 1 | K13: =AVERAGE(F13:J13) -> #DIV/0! | Q13: =AVERAGE(L13:P13) -> #DIV/0! | W13: =AVERAGE(R13:V13) -> #DIV/0! | Z13: =IF(X13>=85,"5",IF(X13>=65,"4",IF(X13>=55,"3",IF(X13>=40,"2",IF(X13>=1,"1",IF(X13>="","0")))))) -> 0 | AA13: =IF(BE13>=4.5, " 5 ", IF(BE13>=3.5," 4 ",IF(BE13>=2.5," 3 ",IF(BE13>=1.5," 2 ",IF(BE13>=1,"1 ",IF(BE13>=0,"0")))))) -> #DIV/0! | AH13: =AVERAGE(AC13:AG13) -> #DIV/0! | AN13: =AVERAGE(AI13:AM13) -> #DIV/0! | AT13: =AVERAGE(AO13:AS13) -> #DIV/0! | AW13: =IF(AU13>=85,"5",IF(AU13>=65,"4",IF(AU13>=55,"3",IF(AU13>=40,"2",IF(AU13>=1,"1",IF(AU13>="","0")))))) -> 0 | AX13: =IF(BJ13>=4.5, " 5 ", IF(BJ13>=3.5," 4 ",IF(BJ13>=2.5," 3 ",IF(BJ13>=1.5," 2 ",IF(BJ13>=1,"1 ",IF(BJ13>=0,"0")))))) -> #DIV/0! | AY13: =IF(BK13>=4.5, " 5 ", IF(BK13>=3.5," 4 ",IF(BK13>=2.5," 3 ",IF(BK13>=1.5," 2 ",IF(BK13>=1,"1 ",IF(BK13>=0,"0")))))) -> #DIV/0! | AZ13: =IF(BP13>=4.5, " 5 ", IF(BP13>=3.5," 4 ",IF(BP13>=2.5," 3 ",IF(BP13>=1.5," 2 ",IF(BP13>=1,"1 ",IF(BP13>=0,"0")))))) -> #DIV/0! | BA13: =$K13*$F$12 -> #DIV/0! | BB13: =Q13*L12 -> #DIV/0! | BC13: =$W13*$R$12 -> #DIV/0! | BD13: =$Z13*$X$12 -> 0 | BE13: =BA13+BB13+BC13+BD13 -> #DIV/0! | BF13: =$AH13*$AC$12 -> #DIV/0! | BG13: =$AN13*$AI$12 -> #DIV/0! | BH13: =$AT13*$AO$12 -> #DIV/0! | BI13: =$AW13*$AU$12 -> 0 | BJ13: =(BF13+BG13+BH13+BI13) -> #DIV/0! | BK13: =(BE13+BJ13)/2 -> #DIV/0! | BL13: =(BE13+BJ13)/2 -> #DIV/0! | BM13: =ROUND(BL13,) -> #DIV/0! | BN13: =ROUND(BO14,) -> #DIV/0! | BO13: =(BE13+BJ13)/2 -> #DIV/0! | BP13: =(AY13+AY14)/2 -> #DIV/0!
E14: 2 | K14: =AVERAGE(F14:J14) -> #DIV/0! | Q14: =AVERAGE(L14:P14) -> #DIV/0! | W14: =AVERAGE(R14:V14) -> #DIV/0! | Z14: =IF(X14>=85,"5",IF(X14>=65,"4",IF(X14>=55,"3",IF(X14>=40,"2",IF(X14>=1,"1",IF(X14>="","0")))))) -> 0 | AA14: =IF(BE14>=4.5, " 5 ", IF(BE14>=3.5," 4 ",IF(BE14>=2.5," 3 ",IF(BE14>=1.5," 2 ",IF(BE14>=1,"1 ",IF(BE14>=0,"0")))))) -> #DIV/0! | AH14: =AVERAGE(AC14:AG14) -> #DIV/0! | AN14: =AVERAGE(AI14:AM14) -> #DIV/0! | AT14: =AVERAGE(AO14:AS14) -> #DIV/0! | AW14: =IF(AU14>=85,"5",IF(AU14>=65,"4",IF(AU14>=55,"3",IF(AU14>=40,"2",IF(AU14>=1,"1",IF(AU14>="","0")))))) -> 0 | AX14: =IF(BJ14>=4.5, " 5 ", IF(BJ14>=3.5," 4 ",IF(BJ14>=2.5," 3 ",IF(BJ14>=1.5," 2 ",IF(BJ14>=1,"1 ",IF(BJ14>=0,"0")))))) -> #DIV/0! | AY14: =IF(BK14>=4.5, " 5 ", IF(BK14>=3.5," 4 ",IF(BK14>=2.5," 3 ",IF(BK14>=1.5," 2 ",IF(BK14>=1,"1 ",IF(BK14>=0,"0")))))) -> #DIV/0! | BA14: =$K14*$F$12 -> #DIV/0! | BB14: =$Q14*$L$12 -> #DIV/0! | BC14: =$W14*$R$12 -> #DIV/0! | BD14: =$Z14*$X$12 -> 0 | BE14: =BA14+BB14+BC14+BD14 -> #DIV/0! | BF14: =$AH14*$AC$12 -> #DIV/0! | BG14: =$AN14*$AI$12 -> #DIV/0! | BH14: =$AT14*$AO$12 -> #DIV/0! | BI14: =$AW14*$AU$12 -> 0 | BJ14: =(BF14+BG14+BH14+BI14) -> #DIV/0! | BK14: =(BE14+BJ14)/2 -> #DIV/0! | BO14: =(BE14+BJ14)/2 -> #DIV/0!
A15: 2 | E15: 1 | K15: =AVERAGE(F15:J15) -> #DIV/0! | Q15: =AVERAGE(L15:P15) -> #DIV/0! | W15: =AVERAGE(R15:V15) -> #DIV/0! | Z15: =IF(X15>=85,"5",IF(X15>=65,"4",IF(X15>=55,"3",IF(X15>=40,"2",IF(X15>=1,"1",IF(X15>="","0")))))) -> 0 | AA15: =IF(BE15>=4.5, " 5 ", IF(BE15>=3.5," 4 ",IF(BE15>=2.5," 3 ",IF(BE15>=1.5," 2 ",IF(BE15>=1,"1 ",IF(BE15>=0,"0")))))) -> #DIV/0! | AH15: =AVERAGE(AC15:AG15) -> #DIV/0! | AN15: =AVERAGE(AI15:AM15) -> #DIV/0! | AT15: =AVERAGE(AO15:AS15) -> #DIV/0! | AW15: =IF(AU15>=85,"5",IF(AU15>=65,"4",IF(AU15>=55,"3",IF(AU15>=40,"2",IF(AU15>=1,"1",IF(AU15>="","0")))))) -> 0 | AX15: =IF(BJ15>=4.5, " 5 ", IF(BJ15>=3.5," 4 ",IF(BJ15>=2.5," 3 ",IF(BJ15>=1.5," 2 ",IF(BJ15>=1,"1 ",IF(BJ15>=0,"0")))))) -> #DIV/0! | AY15: =IF(BK15>=4.5, " 5 ", IF(BK15>=3.5," 4 ",IF(BK15>=2.5," 3 ",IF(BK15>=1.5," 2 ",IF(BK15>=1,"1 ",IF(BK15>=0,"0")))))) -> #DIV/0! | AZ15: =IF(BP15>=4.5, " 5 ", IF(BP15>=3.5," 4 ",IF(BP15>=2.5," 3 ",IF(BP15>=1.5," 2 ",IF(BP15>=1,"1 ",IF(BP15>=0,"0")))))) -> #DIV/0! | BA15: =$K15*$F$12 -> #DIV/0! | BB15: =$Q15*$L$12 -> #DIV/0! | BC15: =$W15*$R$12 -> #DIV/0! | BD15: =$Z15*$X$12 -> 0 | BE15: =BA15+BB15+BC15+BD15 -> #DIV/0! | BF15: =$AH15*$AC$12 -> #DIV/0! | BG15: =$AN15*$AI$12 -> #DIV/0! | BH15: =$AT15*$AO$12 -> #DIV/0! | BI15: =$AW15*$AU$12 -> 0 | BJ15: =(BF15+BG15+BH15+BI15) -> #DIV/0! | BK15: =(BE15+BJ15)/2 -> #DIV/0! | BL15: =(BE15+BJ15)/2 -> #DIV/0! | BM15: =ROUND(BL15,) -> #DIV/0! | BN15: =ROUND(BO16,) -> #DIV/0! | BO15: =(BE15+BJ15)/2 -> #DIV/0! | BP15: =(AY15+AY16)/2 -> #DIV/0!
E16: 2 | K16: =AVERAGE(F16:J16) -> #DIV/0! | Q16: =AVERAGE(L16:P16) -> #DIV/0! | W16: =AVERAGE(R16:V16) -> #DIV/0! | Z16: =IF(X16>=85,"5",IF(X16>=65,"4",IF(X16>=55,"3",IF(X16>=40,"2",IF(X16>=1,"1",IF(X16>="","0")))))) -> 0 | AA16: =IF(BE16>=4.5, " 5 ", IF(BE16>=3.5," 4 ",IF(BE16>=2.5," 3 ",IF(BE16>=1.5," 2 ",IF(BE16>=1,"1 ",IF(BE16>=0,"0")))))) -> #DIV/0! | AH16: =AVERAGE(AC16:AG16) -> #DIV/0! | AN16: =AVERAGE(AI16:AM16) -> #DIV/0! | AT16: =AVERAGE(AO16:AS16) -> #DIV/0! | AW16: =IF(AU16>=85,"5",IF(AU16>=65,"4",IF(AU16>=55,"3",IF(AU16>=40,"2",IF(AU16>=1,"1",IF(AU16>="","0")))))) -> 0 | AX16: =IF(BJ16>=4.5, " 5 ", IF(BJ16>=3.5," 4 ",IF(BJ16>=2.5," 3 ",IF(BJ16>=1.5," 2 ",IF(BJ16>=1,"1 ",IF(BJ16>=0,"0")))))) -> #DIV/0! | AY16: =IF(BK16>=4.5, " 5 ", IF(BK16>=3.5," 4 ",IF(BK16>=2.5," 3 ",IF(BK16>=1.5," 2 ",IF(BK16>=1,"1 ",IF(BK16>=0,"0")))))) -> #DIV/0! | BA16: =$K16*$F$12 -> #DIV/0! | BB16: =$Q16*$L$12 -> #DIV/0! | BC16: =$W16*$R$12 -> #DIV/0! | BD16: =$Z16*$X$12 -> 0 | BE16: =BA16+BB16+BC16+BD16 -> #DIV/0! | BF16: =$AH16*$AC$12 -> #DIV/0! | BG16: =$AN16*$AI$12 -> #DIV/0! | BH16: =$AT16*$AO$12 -> #DIV/0! | BI16: =$AW16*$AU$12 -> 0 | BJ16: =(BF16+BG16+BH16+BI16) -> #DIV/0! | BK16: =(BE16+BJ16)/2 -> #DIV/0! | BO16: =(BE16+BJ16)/2 -> #DIV/0!
A17: 3 | E17: 1 | K17: =AVERAGE(F17:J17) -> #DIV/0! | Q17: =AVERAGE(L17:P17) -> #DIV/0! | W17: =AVERAGE(R17:V17) -> #DIV/0! | Z17: =IF(X17>=85,"5",IF(X17>=65,"4",IF(X17>=55,"3",IF(X17>=40,"2",IF(X17>=1,"1",IF(X17>="","0")))))) -> 0 | AA17: =IF(BE17>=4.5, " 5 ", IF(BE17>=3.5," 4 ",IF(BE17>=2.5," 3 ",IF(BE17>=1.5," 2 ",IF(BE17>=1,"1 ",IF(BE17>=0,"0")))))) -> #DIV/0! | AH17: =AVERAGE(AC17:AG17) -> #DIV/0! | AN17: =AVERAGE(AI17:AM17) -> #DIV/0! | AT17: =AVERAGE(AO17:AS17) -> #DIV/0! | AW17: =IF(AU17>=85,"5",IF(AU17>=65,"4",IF(AU17>=55,"3",IF(AU17>=40,"2",IF(AU17>=1,"1",IF(AU17>="","0")))))) -> 0 | AX17: =IF(BJ17>=4.5, " 5 ", IF(BJ17>=3.5," 4 ",IF(BJ17>=2.5," 3 ",IF(BJ17>=1.5," 2 ",IF(BJ17>=1,"1 ",IF(BJ17>=0,"0")))))) -> #DIV/0! | AY17: =IF(BK17>=4.5, " 5 ", IF(BK17>=3.5," 4 ",IF(BK17>=2.5," 3 ",IF(BK17>=1.5," 2 ",IF(BK17>=1,"1 ",IF(BK17>=0,"0")))))) -> #DIV/0! | AZ17: =IF(BP17>=4.5, " 5 ", IF(BP17>=3.5," 4 ",IF(BP17>=2.5," 3 ",IF(BP17>=1.5," 2 ",IF(BP17>=1,"1 ",IF(BP17>=0,"0")))))) -> #DIV/0! | BA17: =$K17*$F$12 -> #DIV/0! | BB17: =$Q17*$L$12 -> #DIV/0! | BC17: =$W17*$R$12 -> #DIV/0! | BD17: =$Z17*$X$12 -> 0 | BE17: =BA17+BB17+BC17+BD17 -> #DIV/0! | BF17: =$AH17*$AC$12 -> #DIV/0! | BG17: =$AN17*$AI$12 -> #DIV/0! | BH17: =$AT17*$AO$12 -> #DIV/0! | BI17: =$AW17*$AU$12 -> 0 | BJ17: =(BF17+BG17+BH17+BI17) -> #DIV/0! | BK17: =(BE17+BJ17)/2 -> #DIV/0! | BL17: =(BE17+BJ17)/2 -> #DIV/0! | BM17: =ROUND(BL17,) -> #DIV/0! | BN17: =ROUND(BO18,) -> #DIV/0! | BO17: =(BE17+BJ17)/2 -> #DIV/0! | BP17: =(AY17+AY18)/2 -> #DIV/0!
